Workbook

Sheet FORECAST
A1: Day | B1: Date | C1: Forecast | D1: AHT | E1: Shrinkage% | F1: Occupancy%
A2: SAT | B2: 45689 | C2: 529.69189 | D2: 999.29611 | E2: 0.15 | F2: 0.75
A3: SUN | B3: 45690 | C3: 338.66063 | D3: 961.27524 | E3: 0.15 | F3: 0.75
A4: MON | B4: 45691 | C4: 875.60855 | D4: 963.51594 | E4: 0.15 | F4: 0.75
A5: TUE | B5: 45692 | C5: 854.50258 | D5: 978.84904 | E5: 0.15 | F5: 0.75
A6: WED | B6: 45693 | C6: 779.82701 | D6: 944.42176 | E6: 0.15 | F6: 0.75
A7: THU | B7: 45694 | C7: 714.38927 | D7: 961.80709 | E7: 0.15 | F7: 0.75
A8: FRI | B8: 45695 | C8: 690.98297 | D8: 978.46886 | E8: 0.15 | F8: 0.75
A9: SAT | B9: 45696 | C9: 498.97791 | D9: 997.17185 | E9: 0.15 | F9: 0.75
A10: SUN | B10: 45697 | C10: 313.944 | D10: 960.98922 | E10: 0.15 | F10: 0.75
A11: MON | B11: 45698 | C11: 805.754 | D11: 964.5866 | E11: 0.15 | F11: 0.75
A12: TUE | B12: 45699 | C12: 831.77331 | D12: 977.39196 | E12: 0.15 | F12: 0.75
A13: WED | B13: 45700 | C13: 790.20951 | D13: 944.12296 | E13: 0.15 | F13: 0.75
... A300: WED | B300: 45987 | C300: 1747.6422 | D300: 1157.4335 | E300: 0.15 | F300: 0.75
A301: THU | B301: 45988 | E301: 0.15 | F301: 0.75
A302: FRI | B302: 45989 | C302: 1767.5338 | D302: 1157.1781 | E302: 0.15 | F302: 0.75
A303: SAT | B303: 45990 | C303: 1284.7108 | D303: 1157.0656 | E303: 0.15 | F303: 0.75
A304: SUN | B304: 45991 | C304: 899.31487 | D304: 1158.4067 | E304: 0.15 | F304: 0.75
A305: MON | B305: 45992 | C305: 1885 | D305: 1214.9337 | E305: 0.15 | F305: 0.75
A306: TUE | B306: 45993 | C306: 1799 | D306: 1214.925 | E306: 0.15 | F306: 0.75
A307: WED | B307: 45994 | C307: 1756 | D307: 1214.9203 | E307: 0.15 | F307: 0.75
A308: THU | B308: 45995 | C308: 1670 | D308: 1214.9102 | E308: 0.15 | F308: 0.75
A309: FRI | B309: 45996 | C309: 1542 | D309: 1214.9805 | E309: 0.15 | F309: 0.75
A310: SAT | B310: 45997 | C310: 1371 | D310: 1214.9161 | E310: 0.15 | F310: 0.75
A311: SUN | B311: 45998 | C311: 878 | D311: 1214.9203 | E311: 0.15 | F311: 0.75
A312: MON | B312: 45999 | C312: 1699 | D312: 1213.8022 | E312: 0.15 | F312: 0.75
A313: TUE | B313: 46000 | C313: 1628 | D313: 1214.9877 | E313: 0.15 | F313: 0.75
... A328: WED | B328: 46015 | C328: 643 | D328: 1215.0078 | E328: 0.15 | F328: 0.75
A329: THU | B329: 46016 | D329: - | E329: 0.15 | F329: 0.75
A330: FRI | B330: 46017 | C330: 1799 | D330: 1214.925 | E330: 0.15 | F330: 0.75
A331: SAT | B331: 46018 | C331: 1614 | D331: 1213.8166 | E331: 0.15 | F331: 0.75
A332: SUN | B332: 46019 | C332: 1457 | D332: 1214.9279 | E332: 0.15 | F332: 0.75
A333: MON | B333: 46020 | C333: 1414 | D333: 1214.9222 | E333: 0.15 | F333: 0.75
A334: TUE | B334: 46021 | C334: 1242 | D334: 1214.8953 | E334: 0.15 | F334: 0.75
A335: WED | B335: 46022 | C335: 643 | D335: 1215.0078 | E335: 0.15 | F335: 0.75
A336: THU | B336: 46023 | C336: 588 | D336: 1207.483 | E336: 0.15 | F336: 0.75
A337: FRI | B337: 46024 | C337: 1894 | D337: 1207.6558 | E337: 0.15 | F337: 0.75
A338: SAT | B338: 46025 | C338: 1494 | D338: 1207.6975 | E338: 0.15 | F338: 0.75
A339: SUN | B339: 46026 | C339: 838 | D339: 1207.7566 | E339: 0.15 | F339: 0.75
A340: MON | B340: 46027 | C340: 1858 | D340: 1207.6964 | E340: 0.15 | F340: 0.75
...

Sheet BREAKDOWN CALL VOLUME
A1: CALL ARRIVAL PATTERN - AVERAGE CALL PER INTERVALS (PAST DATA) | J1: CALL ARRIVAL PATTERN% | V1: BREAKDOWN FORECAST BASED ON CALL ARRIVAL PATTERN
A3: Dow profile | B3: =B66/SUM($B$66:$H$66) -> 0.17140498 | C3: =C66/SUM($B$66:$H$66) -> 0.17379165 | D3: =D66/SUM($B$66:$H$66) -> 0.17389342 | E3: =E66/SUM($B$66:$H$66) -> 0.15951252 | F3: =F66/SUM($B$66:$H$66) -> 0.14594899 | G3: =G66/SUM($B$66:$H$66) -> 0.10832038 | H3: =H66/SUM($B$66:$H$66) -> 0.067128066 | J3: Distribution% | U3: Forecast | V3: =GETPIVOTDATA("Forecast",$S$5) -> 10901
A4: INTERVAL | B4: MONDAY | C4: TUESDAY | D4: WEDNESDAY | E4: THURSDAY | F4: FRIDAY | G4: SATURDAY | H4: SUNDAY | J4: INTERVAL | K4: MONDAY | L4: TUESDAY | M4: WEDNESDAY | N4: THURSDAY | O4: FRIDAY | P4: SATURDAY | Q4: SUNDAY | V4: INTERVAL | W4: MONDAY | X4: TUESDAY | Y4: WEDNESDAY | Z4: THURSDAY | AA4: FRIDAY | AB4: SATURDAY | AC4: SUNDAY
A5: 0.33333333 | B5: 9.7555556 | C5: 9.4444444 | D5: 9.3777778 | E5: 8.6363636 | F5: 9.3181818 | G5: 5.6829268 | H5: 2.5 | J5: 0.33333333 | K5: =B5/SUM($B$5:$B$65) -> 0.012819815 | L5: =C5/SUM($C$5:$C$65) -> 0.012240543 | M5: =D5/SUM($D$5:$D$65) -> 0.012147026 | N5: =E5/SUM($E$5:$E$65) -> 0.012195211 | O5: =F5/SUM($F$5:$F$65) -> 0.014380807 | P5: =G5/SUM($G$5:$G$65) -> 0.011817214 | Q5: =H5/SUM($H$5:$H$65) -> 0.0083885915 | S5: Row Labels | T5: Sum of Forecast | V5: 0.33333333 | W5: =$V$3*$B$3*K5 -> 23.95364 | X5: =$V$3*$C$3*L5 -> 23.189743 | Y5: =$V$3*$D$3*M5 -> 23.02605 | Z5: =$V$3*$E$3*N5 -> 21.205594 | AA5: =$V$3*$F$3*O5 -> 22.879719 | AB5: =$V$3*$G$3*P5 -> 13.953771 | AC5: =$V$3*$H$3*Q5 -> 6.1384613
A6: 0.34375 | B6: 8.5555556 | C6: 7.6222222 | D6: 8.3181818 | E6: 7.5681818 | F6: 7.8409091 | G6: 4.902439 | H6: 2.452381 | J6: 0.34375 | K6: =B6/SUM($B$5:$B$65) -> 0.01124289 | L6: =C6/SUM($C$5:$C$65) -> 0.0098788381 | M6: =D6/SUM($D$5:$D$65) -> 0.010774533 | N6: =E6/SUM($E$5:$E$65) -> 0.010686856 | O6: =F6/SUM($F$5:$F$65) -> 0.012100923 | P6: =G6/SUM($G$5:$G$65) -> 0.010194249 | Q6: =H6/SUM($H$5:$H$65) -> 0.0082288088 | S6: 45992 | T6: 1885 | V6: 0.34375 | W6: =$V$3*$B$3*K6 -> 21.007179 | X6: =$V$3*$C$3*L6 -> 18.715487 | Y6: =$V$3*$D$3*M6 -> 20.424335 | Z6: =$V$3*$E$3*N6 -> 18.582797 | AA6: =$V$3*$F$3*O6 -> 19.252447 | AB6: =$V$3*$G$3*P6 -> 12.037373 | AC6: =$V$3*$H$3*Q6 -> 6.0215383
A7: 0.35416667 | B7: 7.5111111 | C7: 8.2222222 | D7: 8.0454545 | E7: 7.4545455 | F7: 7.5227273 | G7: 5.3658537 | H7: 2.9047619 | J7: 0.35416667 | K7: =B7/SUM($B$5:$B$65) -> 0.0098703812 | L7: =C7/SUM($C$5:$C$65) -> 0.010656473 | M7: =D7/SUM($D$5:$D$65) -> 0.010421269 | N7: =E7/SUM($E$5:$E$65) -> 0.010526393 | O7: =F7/SUM($F$5:$F$65) -> 0.011609871 | P7: =G7/SUM($G$5:$G$65) -> 0.011157884 | Q7: =H7/SUM($H$5:$H$65) -> 0.0097467444 | S7: 45993 | T7: 1799 | V7: 0.35416667 | W7: =$V$3*$B$3*K7 -> 18.442666 | X7: =$V$3*$C$3*L7 -> 20.188717 | Y7: =$V$3*$D$3*M7 -> 19.754685 | Z7: =$V$3*$E$3*N7 -> 18.303776 | AA7: =$V$3*$F$3*O7 -> 18.471188 | AB7: =$V$3*$G$3*P7 -> 13.175234 | AC7: =$V$3*$H$3*Q7 -> 7.1323074
A8: 0.36458333 | B8: 8.3555556 | C8: 8.5111111 | D8: 8.2045455 | E8: 8 | F8: 8.6136364 | G8: 6.0487805 | H8: 3.2142857 | J8: 0.36458333 | K8: =B8/SUM($B$5:$B$65) -> 0.010980069 | L8: =C8/SUM($C$5:$C$65) -> 0.011030889 | M8: =D8/SUM($D$5:$D$65) -> 0.01062734 | N8: =E8/SUM($E$5:$E$65) -> 0.011296617 | O8: =F8/SUM($F$5:$F$65) -> 0.013293478 | P8: =G8/SUM($G$5:$G$65) -> 0.012577978 | Q8: =H8/SUM($H$5:$H$65) -> 0.010785332 | S8: 45994 | T8: 1756 | V8: 0.36458333 | W8: =$V$3*$B$3*K8 -> 20.516102 | X8: =$V$3*$C$3*L8 -> 20.898051 | Y8: =$V$3*$D$3*M8 -> 20.145314 | Z8: =$V$3*$E$3*N8 -> 19.643076 | AA8: =$V$3*$F$3*O8 -> 21.149789 | AB8: =$V$3*$G$3*P8 -> 14.852082 | AC8: =$V$3*$H$3*Q8 -> 7.8923074
A9: 0.375 | B9: 13.044444 | C9: 12.266667 | D9: 13.113636 | E9: 11.136364 | F9: 10.090909 | G9: 9.6585366 | H9: 4.7857143 | J9: 0.375 | K9: =B9/SUM($B$5:$B$65) -> 0.017141757 | L9: =C9/SUM($C$5:$C$65) -> 0.015898305 | M9: =D9/SUM($D$5:$D$65) -> 0.01698608 | N9: =E9/SUM($E$5:$E$65) -> 0.015725404 | O9: =F9/SUM($F$5:$F$65) -> 0.015573362 | P9: =G9/SUM($G$5:$G$65) -> 0.020084191 | Q9: =H9/SUM($H$5:$H$65) -> 0.016058161 | S9: 45995 | T9: 1670 | V9: 0.375 | W9: =$V$3*$B$3*K9 -> 32.029127 | X9: =$V$3*$C$3*L9 -> 30.119384 | Y9: =$V$3*$D$3*M9 -> 32.19902 | Z9: =$V$3*$E$3*N9 -> 27.344055 | AA9: =$V$3*$F$3*O9 -> 24.777062 | AB9: =$V$3*$G$3*P9 -> 23.715421 | AC9: =$V$3*$H$3*Q9 -> 11.750769
A10: 0.38541667 | B10: 12.355556 | C10: 11.666667 | D10: 10.681818 | E10: 11.25 | F10: 10.954545 | G10: 8.7317073 | H10: 4.3571429 | J10: 0.38541667 | K10: =B10/SUM($B$5:$B$65) -> 0.016236485 | L10: =C10/SUM($C$5:$C$65) -> 0.015120671 | M10: =D10/SUM($D$5:$D$65) -> 0.013836149 | N10: =E10/SUM($E$5:$E$65) -> 0.015885867 | O10: =F10/SUM($F$5:$F$65) -> 0.016906217 | P10: =G10/SUM($G$5:$G$65) -> 0.01815692 | Q10: =H10/SUM($H$5:$H$65) -> 0.014620117 | S10: 45996 | T10: 1542 | V10: 0.38541667 | W10: =$V$3*$B$3*K10 -> 30.33764 | X10: =$V$3*$C$3*L10 -> 28.646153 | Y10: =$V$3*$D$3*M10 -> 26.227971 | Z10: =$V$3*$E$3*N10 -> 27.623076 | AA10: =$V$3*$F$3*O10 -> 26.897621 | AB10: =$V$3*$G$3*P10 -> 21.439699 | AC10: =$V$3*$H$3*Q10 -> 10.698461
A11: 0.39583333 | B11: 11.422222 | C11: 11.533333 | D11: 11.931818 | E11: 11.704545 | F11: 11 | G11: 8.5609756 | H11: 5.5714286 | J11: 0.39583333 | K11: =B11/SUM($B$5:$B$65) -> 0.015009988 | L11: =C11/SUM($C$5:$C$65) -> 0.014947863 | M11: =D11/SUM($D$5:$D$65) -> 0.015455272 | N11: =E11/SUM($E$5:$E$65) -> 0.016527721 | O11: =F11/SUM($F$5:$F$65) -> 0.016976367 | P11: =G11/SUM($G$5:$G$65) -> 0.017801897 | Q11: =H11/SUM($H$5:$H$65) -> 0.018694575 | S11: 45997 | T11: 1371 | V11: 0.39583333 | W11: =$V$3*$B$3*K11 -> 28.045948 | X11: =$V$3*$C$3*L11 -> 28.318768 | Y11: =$V$3*$D$3*M11 -> 29.297202 | Z11: =$V$3*$E$3*N11 -> 28.73916 | AA11: =$V$3*$F$3*O11 -> 27.00923 | AB11: =$V$3*$G$3*P11 -> 21.020487 | AC11: =$V$3*$H$3*Q11 -> 13.68
A12: 0.40625 | B12: 10.911111 | C12: 12.911111 | D12: 12.613636 | E12: 12.068182 | F12: 11.022727 | G12: 10.170732 | H12: 4.6666667 | J12: 0.40625 | K12: =B12/SUM($B$5:$B$65) -> 0.014338335 | L12: =C12/SUM($C$5:$C$65) -> 0.016733542 | M12: =D12/SUM($D$5:$D$65) -> 0.016338431 | N12: =E12/SUM($E$5:$E$65) -> 0.017041203 | O12: =F12/SUM($F$5:$F$65) -> 0.017011442 | P12: =G12/SUM($G$5:$G$65) -> 0.021149262 | Q12: =H12/SUM($H$5:$H$65) -> 0.015658704 | S12: 45998 | T12: 878 | V12: 0.40625 | W12: =$V$3*$B$3*K12 -> 26.790973 | X12: =$V$3*$C$3*L12 -> 31.701743 | Y12: =$V$3*$D$3*M12 -> 30.971328 | Z12: =$V$3*$E$3*N12 -> 29.632027 | AA12: =$V$3*$F$3*O12 -> 27.065034 | AB12: =$V$3*$G$3*P12 -> 24.973057 | AC12: =$V$3*$H$3*Q12 -> 11.458461
A13: 0.41666667 | B13: 12.888889 | C13: 14.6 | D13: 13.25 | E13: 13.340909 | F13: 12.681818 | G13: 10.926829 | H13: 5.8809524 | J13: 0.41666667 | K13: =B13/SUM($B$5:$B$65) -> 0.016937341 | L13: =C13/SUM($C$5:$C$65) -> 0.018922439 | M13: =D13/SUM($D$5:$D$65) -> 0.017162712 | N13: =E13/SUM($E$5:$E$65) -> 0.018838392 | O13: =F13/SUM($F$5:$F$65) -> 0.019571927 | P13: =G13/SUM($G$5:$G$65) -> 0.022721509 | Q13: =H13/SUM($H$5:$H$65) -> 0.019733163 | S13: Grand Total | T13: 10901 | V13: 0.41666667 | W13: =$V$3*$B$3*K13 -> 31.647178 | X13: =$V$3*$C$3*L13 -> 35.848614 | Y13: =$V$3*$D$3*M13 -> 32.533845 | Z13: =$V$3*$E$3*N13 -> 32.757062 | AA13: =$V$3*$F$3*O13 -> 31.13874 | AB13: =$V$3*$G$3*P13 -> 26.829568 | AC13: =$V$3*$H$3*Q13 -> 14.44
A14: 0.42708333 | B14: 13.333333 | C14: 13.088889 | D14: 13.477273 | E14: 13.545455 | F14: 12.363636 | G14: 11.878049 | H14: 6.047619 | J14: 0.42708333 | K14: =B14/SUM($B$5:$B$65) -> 0.017521387 | L14: =C14/SUM($C$5:$C$65) -> 0.016963952 | M14: =D14/SUM($D$5:$D$65) -> 0.017457098 | N14: =E14/SUM($E$5:$E$65) -> 0.019127226 | O14: =F14/SUM($F$5:$F$65) -> 0.019080875 | P14: =G14/SUM($G$5:$G$65) -> 0.024699498 | Q14: =H14/SUM($H$5:$H$65) -> 0.020292402 | V14: 0.42708333 | W14: =$V$3*$B$3*K14 -> 32.73846 | X14: =$V$3*$C$3*L14 -> 32.138255 | Y14: =$V$3*$D$3*M14 -> 33.091887 | Z14: =$V$3*$E$3*N14 -> 33.2593 | AA14: =$V$3*$F$3*O14 -> 30.357481 | AB14: =$V$3*$G$3*P14 -> 29.165177 | AC14: =$V$3*$H$3*Q14 -> 14.84923
A15: 0.4375 | B15: 12.644444 | C15: 13.711111 | D15: 15.613636 | E15: 13.25 | F15: 12.681818 | G15: 11.365854 | H15: 5.2619048 | J15: 0.4375 | K15: =B15/SUM($B$5:$B$65) -> 0.016616115 | L15: =C15/SUM($C$5:$C$65) -> 0.017770388 | M15: =D15/SUM($D$5:$D$65) -> 0.020224328 | N15: =E15/SUM($E$5:$E$65) -> 0.018710022 | O15: =F15/SUM($F$5:$F$65) -> 0.019571927 | P15: =G15/SUM($G$5:$G$65) -> 0.023634427 | Q15: =H15/SUM($H$5:$H$65) -> 0.017655988 | V15: 0.4375 | W15: =$V$3*$B$3*K15 -> 31.046973 | X15: =$V$3*$C$3*L15 -> 33.66605 | Y15: =$V$3*$D$3*M15 -> 38.337481 | Z15: =$V$3*$E$3*N15 -> 32.533845 | AA15: =$V$3*$F$3*O15 -> 31.13874 | AB15: =$V$3*$G$3*P15 -> 27.907541 | AC15: =$V$3*$H$3*Q15 -> 12.92
A16: 0.44791667 | B16: 13.2 | C16: 14.911111 | D16: 14.363636 | E16: 12.772727 | F16: 12.318182 | G16: 11.536585 | H16: 5.8571429 | J16: 0.44791667 | K16: =B16/SUM($B$5:$B$65) -> 0.017346173 | L16: =C16/SUM($C$5:$C$65) -> 0.019325657 | M16: =D16/SUM($D$5:$D$65) -> 0.018605204 | N16: =E16/SUM($E$5:$E$65) -> 0.018036076 | O16: =F16/SUM($F$5:$F$65) -> 0.019010725 | P16: =G16/SUM($G$5:$G$65) -> 0.023989451 | Q16: =H16/SUM($H$5:$H$65) -> 0.019653272 | V16: 0.44791667 | W16: =$V$3*$B$3*K16 -> 32.411076 | X16: =$V$3*$C$3*L16 -> 36.612512 | Y16: =$V$3*$D$3*M16 -> 35.268251 | Z16: =$V$3*$E$3*N16 -> 31.361957 | AA16: =$V$3*$F$3*O16 -> 30.245873 | AB16: =$V$3*$G$3*P16 -> 28.326753 | AC16: =$V$3*$H$3*Q16 -> 14.381538
A17: 0.45833333 | B17: 16.022222 | C17: 17.4 | D17: 20.568182 | E17: 15.522727 | F17: 16.909091 | G17: 12.731707 | H17: 7.0238095 | J17: 0.45833333 | K17: =B17/SUM($B$5:$B$65) -> 0.021054866 | L17: =C17/SUM($C$5:$C$65) -> 0.0225514 | M17: =D17/SUM($D$5:$D$65) -> 0.026641946 | N17: =E17/SUM($E$5:$E$65) -> 0.021919288 | O17: =F17/SUM($F$5:$F$65) -> 0.026095903 | P17: =G17/SUM($G$5:$G$65) -> 0.026474616 | Q17: =H17/SUM($H$5:$H$65) -> 0.023567948 | V17: 0.45833333 | W17: =$V$3*$B$3*K17 -> 39.340717 | X17: =$V$3*$C$3*L17 -> 42.723691 | Y17: =$V$3*$D$3*M17 -> 50.502795 | Z17: =$V$3*$E$3*N17 -> 38.114264 | AA17: =$V$3*$F$3*O17 -> 41.51832 | AB17: =$V$3*$G$3*P17 -> 31.261237 | AC17: =$V$3*$H$3*Q17 -> 17.246153
A18: 0.46875 | B18: 15.733333 | C18: 16.555556 | D18: 17.454545 | E18: 15.431818 | F18: 15.681818 | G18: 13.195122 | H18: 7.1428571 | J18: 0.46875 | K18: =B18/SUM($B$5:$B$65) -> 0.020675236 | L18: =C18/SUM($C$5:$C$65) -> 0.021456952 | M18: =D18/SUM($D$5:$D$65) -> 0.022608855 | N18: =E18/SUM($E$5:$E$65) -> 0.021790917 | O18: =F18/SUM($F$5:$F$65) -> 0.024201846 | P18: =G18/SUM($G$5:$G$65) -> 0.027438251 | Q18: =H18/SUM($H$5:$H$65) -> 0.023967404 | V18: 0.46875 | W18: =$V$3*$B$3*K18 -> 38.631383 | X18: =$V$3*$C$3*L18 -> 40.650255 | Y18: =$V$3*$D$3*M18 -> 42.857621 | Z18: =$V$3*$E$3*N18 -> 37.891048 | AA18: =$V$3*$F$3*O18 -> 38.504894 | AB18: =$V$3*$G$3*P18 -> 32.399098 | AC18: =$V$3*$H$3*Q18 -> 17.538461
A19: 0.47916667 | B19: 16.022222 | C19: 16.888889 | D19: 17.136364 | E19: 15.613636 | F19: 14.636364 | G19: 12.731707 | H19: 7 | J19: 0.47916667 | K19: =B19/SUM($B$5:$B$65) -> 0.021054866 | L19: =C19/SUM($C$5:$C$65) -> 0.021888971 | M19: =D19/SUM($D$5:$D$65) -> 0.022196715 | N19: =E19/SUM($E$5:$E$65) -> 0.022047659 | O19: =F19/SUM($F$5:$F$65) -> 0.022588389 | P19: =G19/SUM($G$5:$G$65) -> 0.026474616 | Q19: =H19/SUM($H$5:$H$65) -> 0.023488056 | V19: 0.47916667 | W19: =$V$3*$B$3*K19 -> 39.340717 | X19: =$V$3*$C$3*L19 -> 41.468717 | Y19: =$V$3*$D$3*M19 -> 42.076362 | Z19: =$V$3*$E$3*N19 -> 38.337481 | AA19: =$V$3*$F$3*O19 -> 35.937901 | AB19: =$V$3*$G$3*P19 -> 31.261237 | AC19: =$V$3*$H$3*Q19 -> 17.187692
A20: 0.48958333 | B20: 14.822222 | C20: 16.8 | D20: 17.272727 | E20: 14.431818 | F20: 13.318182 | G20: 12 | H20: 7.3571429 | J20: 0.48958333 | K20: =B20/SUM($B$5:$B$65) -> 0.019477942 | L20: =C20/SUM($C$5:$C$65) -> 0.021773766 | M20: =D20/SUM($D$5:$D$65) -> 0.022373347 | N20: =E20/SUM($E$5:$E$65) -> 0.02037884 | O20: =F20/SUM($F$5:$F$65) -> 0.020554031 | P20: =G20/SUM($G$5:$G$65) -> 0.024953086 | Q20: =H20/SUM($H$5:$H$65) -> 0.024686426 | V20: 0.48958333 | W20: =$V$3*$B$3*K20 -> 36.394255 | X20: =$V$3*$C$3*L20 -> 41.25046 | Y20: =$V$3*$D$3*M20 -> 42.411187 | Z20: =$V$3*$E$3*N20 -> 35.435663 | AA20: =$V$3*$F$3*O20 -> 32.701258 | AB20: =$V$3*$G$3*P20 -> 29.464614 | AC20: =$V$3*$H$3*Q20 -> 18.064615
A21: 0.5 | B21: 16.066667 | C21: 17.688889 | D21: 17.522727 | E21: 15.931818 | F21: 14.159091 | G21: 14.219512 | H21: 8.3095238 | J21: 0.5 | K21: =B21/SUM($B$5:$B$65) -> 0.021113271 | L21: =C21/SUM($C$5:$C$65) -> 0.022925817 | M21: =D21/SUM($D$5:$D$65) -> 0.022697171 | N21: =E21/SUM($E$5:$E$65) -> 0.022496956 | O21: =F21/SUM($F$5:$F$65) -> 0.021851811 | P21: =G21/SUM($G$5:$G$65) -> 0.029568393 | Q21: =H21/SUM($H$5:$H$65) -> 0.02788208 | V21: 0.5 | W21: =$V$3*$B$3*K21 -> 39.449845 | X21: =$V$3*$C$3*L21 -> 43.433024 | Y21: =$V$3*$D$3*M21 -> 43.025033 | Z21: =$V$3*$E$3*N21 -> 39.11874 | AA21: =$V$3*$F$3*O21 -> 34.766013 | AB21: =$V$3*$G$3*P21 -> 34.91437 | AC21: =$V$3*$H$3*Q21 -> 20.403076
A22: 0.51041667 | B22: 15.022222 | C22: 16.244444 | D22: 14.386364 | E22: 12.977273 | F22: 14.454545 | G22: 12.170732 | H22: 8.0952381 | J22: 0.51041667 | K22: =B22/SUM($B$5:$B$65) -> 0.019740762 | L22: =C22/SUM($C$5:$C$65) -> 0.021053734 | M22: =D22/SUM($D$5:$D$65) -> 0.018634643 | N22: =E22/SUM($E$5:$E$65) -> 0.01832491 | O22: =F22/SUM($F$5:$F$65) -> 0.022307788 | P22: =G22/SUM($G$5:$G$65) -> 0.02530811 | Q22: =H22/SUM($H$5:$H$65) -> 0.027163058 | V22: 0.51041667 | W22: =$V$3*$B$3*K22 -> 36.885332 | X22: =$V$3*$C$3*L22 -> 39.886358 | Y22: =$V$3*$D$3*M22 -> 35.324055 | Z22: =$V$3*$E$3*N22 -> 31.864195 | AA22: =$V$3*$F$3*O22 -> 35.491467 | AB22: =$V$3*$G$3*P22 -> 29.883826 | AC22: =$V$3*$H$3*Q22 -> 19.876922
A23: 0.52083333 | B23: 15.444444 | C23: 14 | D23: 15.204545 | E23: 14.318182 | F23: 13.136364 | G23: 11.97561 | H23: 7.5238095 | J23: 0.52083333 | K23: =B23/SUM($B$5:$B$65) -> 0.020295606 | L23: =C23/SUM($C$5:$C$65) -> 0.018144805 | M23: =D23/SUM($D$5:$D$65) -> 0.019694433 | N23: =E23/SUM($E$5:$E$65) -> 0.020218377 | O23: =F23/SUM($F$5:$F$65) -> 0.02027343 | P23: =G23/SUM($G$5:$G$65) -> 0.024902369 | Q23: =H23/SUM($H$5:$H$65) -> 0.025245666 | V23: 0.52083333 | W23: =$V$3*$B$3*K23 -> 37.92205 | X23: =$V$3*$C$3*L23 -> 34.375383 | Y23: =$V$3*$D$3*M23 -> 37.333006 | Z23: =$V$3*$E$3*N23 -> 35.156642 | AA23: =$V$3*$F$3*O23 -> 32.254824 | AB23: =$V$3*$G$3*P23 -> 29.404727 | AC23: =$V$3*$H$3*Q23 -> 18.473846
A24: 0.53125 | B24: 15.844444 | C24: 16.155556 | D24: 14.295455 | E24: 13.045455 | F24: 13.727273 | G24: 12.317073 | H24: 7 | J24: 0.53125 | K24: =B24/SUM($B$5:$B$65) -> 0.020821248 | L24: =C24/SUM($C$5:$C$65) -> 0.020938529 | M24: =D24/SUM($D$5:$D$65) -> 0.018516888 | N24: =E24/SUM($E$5:$E$65) -> 0.018421188 | O24: =F24/SUM($F$5:$F$65) -> 0.021185384 | P24: =G24/SUM($G$5:$G$65) -> 0.025612416 | Q24: =H24/SUM($H$5:$H$65) -> 0.023488056 | V24: 0.53125 | W24: =$V$3*$B$3*K24 -> 38.904204 | X24: =$V$3*$C$3*L24 -> 39.668101 | Y24: =$V$3*$D$3*M24 -> 35.100838 | Z24: =$V$3*$E$3*N24 -> 32.031607 | AA24: =$V$3*$F$3*O24 -> 33.705733 | AB24: =$V$3*$G$3*P24 -> 30.243151 | AC24: =$V$3*$H$3*Q24 -> 17.187692
A25: 0.54166667 | B25: 16.111111 | C25: 16.355556 | D25: 15.159091 | E25: 15.568182 | F25: 13.295455 | G25: 13.658537 | H25: 8.3333333 | J25: 0.54166667 | K25: =B25/SUM($B$5:$B$65) -> 0.021171676 | L25: =C25/SUM($C$5:$C$65) -> 0.02119774 | M25: =D25/SUM($D$5:$D$65) -> 0.019635555 | N25: =E25/SUM($E$5:$E$65) -> 0.021983473 | O25: =F25/SUM($F$5:$F$65) -> 0.020518956 | P25: =G25/SUM($G$5:$G$65) -> 0.028401887 | Q25: =H25/SUM($H$5:$H$65) -> 0.027961972 | V25: 0.54166667 | W25: =$V$3*$B$3*K25 -> 39.558973 | X25: =$V$3*$C$3*L25 -> 40.159178 | Y25: =$V$3*$D$3*M25 -> 37.221397 | Z25: =$V$3*$E$3*N25 -> 38.225873 | AA25: =$V$3*$F$3*O25 -> 32.645453 | AB25: =$V$3*$G$3*P25 -> 33.536959 | AC25: =$V$3*$H$3*Q25 -> 20.461538
... A64: 0.94791667 | B64: 0 | C64: 0 | D64: 0.13157895 | E64: 0 | F64: 0 | G64: 0 | H64: 0 | J64: 0.94791667 | K64: =B64/SUM($B$5:$B$65) -> 0 | L64: =C64/SUM($C$5:$C$65) -> 0 | M64: =D64/SUM($D$5:$D$65) -> 0.00017043408 | N64: =E64/SUM($E$5:$E$65) -> 0 | O64: =F64/SUM($F$5:$F$65) -> 0 | P64: =G64/SUM($G$5:$G$65) -> 0 | Q64: =H64/SUM($H$5:$H$65) -> 0 | V64: 0.94791667 | W64: =$V$3*$B$3*K64 -> 0 | X64: =$V$3*$C$3*L64 -> 0 | Y64: =$V$3*$D$3*M64 -> 0.32307691 | Z64: =$V$3*$E$3*N64 -> 0 | AA64: =$V$3*$F$3*O64 -> 0 | AB64: =$V$3*$G$3*P64 -> 0 | AC64: =$V$3*$H$3*Q64 -> 0
A65: 0.95833333 | C65: 0 | D65: 1 | F65: 0 | G65: 0 | H65: 0 | J65: 0.95833333 | K65: =B65/SUM($B$5:$B$65) -> 0 | L65: =C65/SUM($C$5:$C$65) -> 0 | M65: =D65/SUM($D$5:$D$65) -> 0.001295299 | N65: =E65/SUM($E$5:$E$65) -> 0 | O65: =F65/SUM($F$5:$F$65) -> 0 | P65: =G65/SUM($G$5:$G$65) -> 0 | Q65: =H65/SUM($H$5:$H$65) -> 0 | V65: 0.95833333 | W65: =$V$3*$B$3*K65 -> 0 | X65: =$V$3*$C$3*L65 -> 0 | Y65: =$V$3*$D$3*M65 -> 2.4553845 | Z65: =$V$3*$E$3*N65 -> 0 | AA65: =$V$3*$F$3*O65 -> 0 | AB65: =$V$3*$G$3*P65 -> 0 | AC65: =$V$3*$H$3*Q65 -> 0
A66: Total | B66: =SUM(B5:B65) -> 760.97477 | C66: =SUM(C5:C65) -> 771.57072 | D66: =SUM(D5:D65) -> 772.02251 | E66: =SUM(E5:E65) -> 708.17662 | F66: =SUM(F5:F65) -> 647.9596 | G66: =SUM(G5:G65) -> 480.90244 | H66: =SUM(H5:H65) -> 298.02381 | V66: Total | W66: =SUM(W5:W65) -> 1868.4857 | X66: =SUM(X5:X65) -> 1894.5028 | Y66: =SUM(Y5:Y65) -> 1895.6121 | Z66: =SUM(Z5:Z65) -> 1738.8459 | AA66: =SUM(AA5:AA65) -> 1590.99 | AB66: =SUM(AB5:AB65) -> 1180.8004 | AC66: =SUM(AC5:AC65) -> 731.76305 | AD66: =SUM(W66:AC66) -> 10901
A67: Dow profile | B67: =B66/SUM($B$66:$H$66) -> 0.17140498 | C67: =C66/SUM($B$66:$H$66) -> 0.17379165 | D67: =D66/SUM($B$66:$H$66) -> 0.17389342 | E67: =E66/SUM($B$66:$H$66) -> 0.15951252 | F67: =F66/SUM($B$66:$H$66) -> 0.14594899 | G67: =G66/SUM($B$66:$H$66) -> 0.10832038 | H67: =H66/SUM($B$66:$H$66) -> 0.067128066 | I67: =SUM(B67:H67) -> 1 | V67: Dow profile | W67: =W66/SUM($W$66:$AC$66) -> 0.17140498 | X67: =X66/SUM($W$66:$AC$66) -> 0.17379165 | Y67: =Y66/SUM($W$66:$AC$66) -> 0.17389342 | Z67: =Z66/SUM($W$66:$AC$66) -> 0.15951252 | AA67: =AA66/SUM($W$66:$AC$66) -> 0.14594899 | AB67: =AB66/SUM($W$66:$AC$66) -> 0.10832038 | AC67: =AC66/SUM($W$66:$AC$66) -> 0.067128066 | AD67: =SUM(W67:AC67) -> 1

Sheet BREAKDOWN AHT
A1: AHT PATTERN - AVERAGE PER INTERVAL (PAST DATA) | K1: AHT BEHAVIOR PER INTERVAL | W1: BREAKDOWN FORECAST BASED ON AHT BEHAVIOR | AG1: BREAKDOWN FORECAST BASED ON BEHAVIOR - DIFFERENT CONDITIONAL (COMPARISON BEETWEN THE SAME INTERVAL ALONG THE WEEK) TO IDENTIFY DAYS WITH HIGHTEST AHT AT SPECIFIC INTERVALS
A3: Dow profile | B3: =B67 -> 0.99458064 | C3: =C67 -> 0.96510148 | D3: =D67 -> 0.99662811 | E3: =E67 -> 1.0277979 | F3: =F67 -> 0.99172919 | G3: =G67 -> 1.0896623 | H3: =H67 -> 0.92016878 | K3: Distribution% | V3: Forecast AHT | W3: 1214
A4: INTERVAL | B4: MONDAY | C4: TUESDAY | D4: WEDNESDAY | E4: THURSDAY | F4: FRIDAY | G4: SATURDAY | H4: SUNDAY | K4: INTERVAL | L4: MONDAY | M4: TUESDAY | N4: WEDNESDAY | O4: THURSDAY | P4: FRIDAY | Q4: SATURDAY | R4: SUNDAY | W4: INTERVAL | X4: MONDAY | Y4: TUESDAY | Z4: WEDNESDAY | AA4: THURSDAY | AB4: FRIDAY | AC4: SATURDAY | AD4: SUNDAY | AG4: INTERVAL | AH4: MONDAY | AI4: TUESDAY | AJ4: WEDNESDAY | AK4: THURSDAY | AL4: FRIDAY | AM4: SATURDAY | AN4: SUNDAY
A5: 0.33333333 | B5: 386.125 | C5: 391.875 | D5: 393.2 | E5: 422.3 | F5: 380.3 | G5: 352.625 | H5: 320 | K5: 0.33333333 | L5: =B5/B66 -> 0.30646129 | M5: =C5/$C$66 -> 0.32052528 | N5: =D5/$D$66 -> 0.31143548 | O5: =E5/$E$66 -> 0.32434043 | P5: =F5/$F$66 -> 0.30270594 | Q5: =G5/$G$66 -> 0.25545176 | R5: =H5/$H$66 -> 0.2745176 | T5: Row Labels | U5: Average of AHT | W5: 0.33333333 | X5: =L5*X$66 -> 370.02777 | Y5: =M5*Y$66 -> 375.53806 | Z5: =N5*Z$66 -> 376.80782 | AA5: =O5*AA$66 -> 404.69467 | AB5: =P5*AB$66 -> 364.44561 | AC5: =Q5*AC$66 -> 337.92436 | AD5: =R5*AD$66 -> 306.65947 | AG5: 0.33333333 | AH5: =X5 -> 370.02777 | AI5: =Y5 -> 375.53806 | AJ5: =Z5 -> 376.80782 | AK5: =AA5 -> 404.69467 | AL5: =AB5 -> 364.44561 | AM5: =AC5 -> 337.92436 | AN5: =AD5 -> 306.65947
A6: 0.34375 | B6: 758.25 | C6: 848.125 | D6: 969.2 | E6: 1331.4 | F6: 956.3 | G6: 598.875 | H6: 720.25 | K6: 0.34375 | L6: =B6/$B$66 -> 0.60181101 | M6: =C6/$C$66 -> 0.69370463 | N6: =D6/$D$66 -> 0.76765836 | O6: =E6/$E$66 -> 1.0225594 | P6: =F6/$F$66 -> 0.76118246 | Q6: =G6/$G$66 -> 0.43384238 | R6: =H6/$H$66 -> 0.61787907 | T6: 45992 | U6: 1214.9337 | W6: 0.34375 | X6: =L6*X$66 -> 726.63919 | Y6: =M6*Y$66 -> 812.76738 | Z6: =N6*Z$66 -> 928.79486 | AA6: =O6*AA$66 -> 1275.895 | AB6: =P6*AB$66 -> 916.43265 | AC6: =Q6*AC$66 -> 573.9084 | AD6: =R6*AD$66 -> 690.22338 | AG6: 0.34375 | AH6: =X6 -> 726.63919 | AI6: =Y6 -> 812.76738 | AJ6: =Z6 -> 928.79486 | AK6: =AA6 -> 1275.895 | AL6: =AB6 -> 916.43265 | AM6: =AC6 -> 573.9084 | AN6: =AD6 -> 690.22338
A7: 0.35416667 | B7: 1247.5 | C7: 1316.25 | D7: 1304.2 | E7: 1301.5 | F7: 1004.4 | G7: 1345.75 | H7: 1049.625 | K7: 0.35416667 | L7: =B7/$B$66 -> 0.99012098 | M7: =C7/$C$66 -> 1.0765969 | N7: =D7/$D$66 -> 1.0329963 | O7: =E7/$E$66 -> 0.99959523 | P7: =F7/$F$66 -> 0.79946843 | Q7: =G7/$G$66 -> 0.97490025 | R7: =H7/$H$66 -> 0.90043918 | T7: 45993 | U7: 1214.925 | W7: 0.35416667 | X7: =L7*X$66 -> 1195.4928 | Y7: =M7*Y$66 -> 1261.3766 | Z7: =N7*Z$66 -> 1249.829 | AA7: =O7*AA$66 -> 1247.2415 | AB7: =P7*AB$66 -> 962.5274 | AC7: =Q7*AC$66 -> 1289.6468 | AD7: =R7*AD$66 -> 1005.867 | AG7: 0.35416667 | AH7: =X7 -> 1195.4928 | AI7: =Y7 -> 1261.3766 | AJ7: =Z7 -> 1249.829 | AK7: =AA7 -> 1247.2415 | AL7: =AB7 -> 962.5274 | AM7: =AC7 -> 1289.6468 | AN7: =AD7 -> 1005.867
A8: 0.36458333 | B8: 1070.125 | C8: 1503.625 | D8: 1332.4 | E8: 1449.7 | F8: 1008.6 | G8: 1314.125 | H8: 671.5 | K8: 0.36458333 | L8: =B8/$B$66 -> 0.84934126 | M8: =C8/$C$66 -> 1.229856 | N8: =D8/$D$66 -> 1.0553322 | O8: =E8/$E$66 -> 1.1134178 | P8: =F8/$F$66 -> 0.80281149 | Q8: =G8/$G$66 -> 0.95199019 | R8: =H8/$H$66 -> 0.57605803 | T8: 45994 | U8: 1214.9203 | W8: 0.36458333 | X8: =L8*X$66 -> 1025.5124 | Y8: =M8*Y$66 -> 1440.9401 | Z8: =N8*Z$66 -> 1276.8534 | AA8: =O8*AA$66 -> 1389.2632 | AB8: =P8*AB$66 -> 966.55231 | AC8: =Q8*AC$66 -> 1259.3402 | AD8: =R8*AD$66 -> 643.50572 | AG8: 0.36458333 | AH8: =X8 -> 1025.5124 | AI8: =Y8 -> 1440.9401 | AJ8: =Z8 -> 1276.8534 | AK8: =AA8 -> 1389.2632 | AL8: =AB8 -> 966.55231 | AM8: =AC8 -> 1259.3402 | AN8: =AD8 -> 643.50572
A9: 0.375 | B9: 1072.625 | C9: 981.375 | D9: 1143.7 | E9: 1205 | F9: 1144.2 | G9: 1508.75 | H9: 829.625 | K9: 0.375 | L9: =B9/$B$66 -> 0.85132547 | M9: =C9/$C$66 -> 0.80269345 | N9: =D9/$D$66 -> 0.90587171 | O9: =E9/$E$66 -> 0.92548003 | P9: =F9/$F$66 -> 0.9107445 | Q9: =G9/$G$66 -> 1.0929822 | R9: =H9/$H$66 -> 0.71170833 | T9: 45995 | U9: 1214.9102 | W9: 0.375 | X9: =L9*X$66 -> 1027.9082 | Y9: =M9*Y$66 -> 940.46229 | Z9: =N9*Z$66 -> 1096.0201 | AA9: =O9*AA$66 -> 1154.7646 | AB9: =P9*AB$66 -> 1096.4993 | AC9: =Q9*AC$66 -> 1445.8515 | AD9: =R9*AD$66 -> 795.03863 | AG9: 0.375 | AH9: =X9 -> 1027.9082 | AI9: =Y9 -> 940.46229 | AJ9: =Z9 -> 1096.0201 | AK9: =AA9 -> 1154.7646 | AL9: =AB9 -> 1096.4993 | AM9: =AC9 -> 1445.8515 | AN9: =AD9 -> 795.03863
A10: 0.38541667 | B10: 1062.125 | C10: 921.5 | D10: 1860 | E10: 1017.6 | F10: 1322 | G10: 1245.625 | H10: 873.125 | K10: 0.38541667 | L10: =B10/$B$66 -> 0.84299178 | M10: =C10/$C$66 -> 0.75372005 | N10: =D10/$D$66 -> 1.4732197 | O10: =E10/$E$66 -> 0.7815506 | P10: =F10/$F$66 -> 1.0522673 | Q10: =G10/$G$66 -> 0.9023668 | R10: =H10/$H$66 -> 0.74902557 | T10: 45996 | U10: 1214.9805 | W10: 0.38541667 | X10: =L10*X$66 -> 1017.8459 | Y10: =M10*Y$66 -> 883.08343 | Z10: =N10*Z$66 -> 1782.4582 | AA10: =O10*AA$66 -> 975.1771 | AB10: =P10*AB$66 -> 1266.8869 | AC10: =Q10*AC$66 -> 1193.6959 | AD10: =R10*AD$66 -> 836.72515 | AG10: 0.38541667 | AH10: =X10 -> 1017.8459 | AI10: =Y10 -> 883.08343 | AJ10: =Z10 -> 1782.4582 | AK10: =AA10 -> 975.1771 | AL10: =AB10 -> 1266.8869 | AM10: =AC10 -> 1193.6959 | AN10: =AD10 -> 836.72515
A11: 0.39583333 | B11: 1301.75 | C11: 1207.375 | D11: 1127.6 | E11: 1171 | F11: 1228.9 | G11: 1472.25 | H11: 789.75 | K11: 0.39583333 | L11: =B11/$B$66 -> 1.0331783 | M11: =C11/$C$66 -> 0.98754503 | N11: =D11/$D$66 -> 0.89311965 | O11: =E11/$E$66 -> 0.8993669 | P11: =F11/$F$66 -> 0.97816284 | Q11: =G11/$G$66 -> 1.0665405 | R11: =H11/$H$66 -> 0.67750086 | T11: 45997 | U11: 1214.9161 | W11: 0.39583333 | X11: =L11*X$66 -> 1247.4811 | Y11: =M11*Y$66 -> 1157.0405 | Z11: =N11*Z$66 -> 1080.5913 | AA11: =O11*AA$66 -> 1122.182 | AB11: =P11*AB$66 -> 1177.6682 | AC11: =Q11*AC$66 -> 1410.8731 | AD11: =R11*AD$66 -> 756.82598 | AG11: 0.39583333 | AH11: =X11 -> 1247.4811 | AI11: =Y11 -> 1157.0405 | AJ11: =Z11 -> 1080.5913 | AK11: =AA11 -> 1122.182 | AL11: =AB11 -> 1177.6682 | AM11: =AC11 -> 1410.8731 | AN11: =AD11 -> 756.82598
A12: 0.40625 | B12: 1740.375 | C12: 1200 | D12: 1108.1 | E12: 1595 | F12: 1222.7 | G12: 1074.375 | H12: 1142.25 | K12: 0.40625 | L12: =B12/$B$66 -> 1.3813081 | M12: =C12/$C$66 -> 0.98151282 | N12: =D12/$D$66 -> 0.87767461 | O12: =E12/$E$66 -> 1.225013 | P12: =F12/$F$66 -> 0.97322785 | Q12: =G12/$G$66 -> 0.77830835 | R12: =H12/$H$66 -> 0.97989916 | T12: 45998 | U12: 1214.9203 | W12: 0.40625 | X12: =L12*X$66 -> 1667.8202 | Y12: =M12*Y$66 -> 1149.973 | Z12: =N12*Z$66 -> 1061.9042 | AA12: =O12*AA$66 -> 1528.5058 | AB12: =P12*AB$66 -> 1171.7267 | AC12: =Q12*AC$66 -> 1029.5852 | AD12: =R12*AD$66 -> 1094.6305 | AG12: 0.40625 | AH12: =X12 -> 1667.8202 | AI12: =Y12 -> 1149.973 | AJ12: =Z12 -> 1061.9042 | AK12: =AA12 -> 1528.5058 | AL12: =AB12 -> 1171.7267 | AM12: =AC12 -> 1029.5852 | AN12: =AD12 -> 1094.6305
A13: 0.41666667 | B13: 1003 | C13: 1058.375 | D13: 948.5 | E13: 1088 | F13: 1257.4 | G13: 923.625 | H13: 1412.25 | K13: 0.41666667 | L13: =B13/$B$66 -> 0.79606521 | M13: =C13/$C$66 -> 0.86567385 | N13: =D13/$D$66 -> 0.75126285 | O13: =E13/$E$66 -> 0.83562014 | P13: =F13/$F$66 -> 1.0008479 | Q13: =G13/$G$66 -> 0.66910068 | R13: =H13/$H$66 -> 1.2115234 | T13: Grand Total | U13: 1214.9294 | W13: 0.41666667 | X13: =L13*X$66 -> 961.18577 | Y13: =M13*Y$66 -> 1014.2522 | Z13: =N13*Z$66 -> 908.95783 | AA13: =O13*AA$66 -> 1042.6422 | AB13: =P13*AB$66 -> 1204.98 | AC13: =Q13*AC$66 -> 885.11984 | AD13: =R13*AD$66 -> 1353.3745 | AG13: 0.41666667 | AH13: =X13 -> 961.18577 | AI13: =Y13 -> 1014.2522 | AJ13: =Z13 -> 908.95783 | AK13: =AA13 -> 1042.6422 | AL13: =AB13 -> 1204.98 | AM13: =AC13 -> 885.11984 | AN13: =AD13 -> 1353.3745
A14: 0.42708333 | B14: 1128.25 | C14: 1256.25 | D14: 1567.6 | E14: 1538 | F14: 1482.2 | G14: 1203.25 | H14: 811.625 | K14: 0.42708333 | L14: =B14/$B$66 -> 0.89547415 | M14: =C14/$C$66 -> 1.0275212 | N14: =D14/$D$66 -> 1.2416232 | O14: =E14/$E$66 -> 1.1812351 | P14: =F14/$F$66 -> 1.1797811 | Q14: =G14/$G$66 -> 0.87166913 | R14: =H14/$H$66 -> 0.69626671 | W14: 0.42708333 | X14: =L14*X$66 -> 1081.2142 | Y14: =M14*Y$66 -> 1203.878 | Z14: =N14*Z$66 -> 1502.2481 | AA14: =O14*AA$66 -> 1473.8821 | AB14: =P14*AB$66 -> 1420.4083 | AC14: =Q14*AC$66 -> 1153.0875 | AD14: =R14*AD$66 -> 777.78903 | AG14: 0.42708333 | AH14: =X14 -> 1081.2142 | AI14: =Y14 -> 1203.878 | AJ14: =Z14 -> 1502.2481 | AK14: =AA14 -> 1473.8821 | AL14: =AB14 -> 1420.4083 | AM14: =AC14 -> 1153.0875 | AN14: =AD14 -> 777.78903
A15: 0.4375 | B15: 1418.5 | C15: 1317.375 | D15: 1196.4 | E15: 1121.9 | F15: 1090.1 | G15: 1322.625 | H15: 1615.5 | K15: 0.4375 | L15: =B15/$B$66 -> 1.125841 | M15: =C15/$C$66 -> 1.077517 | N15: =D15/$D$66 -> 0.94761294 | O15: =E15/$E$66 -> 0.86165647 | P15: =F15/$F$66 -> 0.86768273 | Q15: =G15/$G$66 -> 0.95814783 | R15: =H15/$H$66 -> 1.385885 | W15: 0.4375 | X15: =L15*X$66 -> 1359.3639 | Y15: =M15*Y$66 -> 1262.4547 | Z15: =N15*Z$66 -> 1146.5231 | AA15: =O15*AA$66 -> 1075.1289 | AB15: =P15*AB$66 -> 1044.6546 | AC15: =Q15*AC$66 -> 1267.4859 | AD15: =R15*AD$66 -> 1548.1512 | AG15: 0.4375 | AH15: =X15 -> 1359.3639 | AI15: =Y15 -> 1262.4547 | AJ15: =Z15 -> 1146.5231 | AK15: =AA15 -> 1075.1289 | AL15: =AB15 -> 1044.6546 | AM15: =AC15 -> 1267.4859 | AN15: =AD15 -> 1548.1512
A16: 0.44791667 | B16: 1415.875 | C16: 1081.375 | D16: 1265.1 | E16: 1267.8 | F16: 1212.7 | G16: 1229.125 | H16: 1050.625 | K16: 0.44791667 | L16: =B16/$B$66 -> 1.1237576 | M16: =C16/$C$66 -> 0.88448618 | N16: =D16/$D$66 -> 1.002027 | O16: =E16/$E$66 -> 0.97371251 | P16: =F16/$F$66 -> 0.96526819 | Q16: =G16/$G$66 -> 0.89041373 | R16: =H16/$H$66 -> 0.90129705 | W16: 0.44791667 | X16: =L16*X$66 -> 1356.8484 | Y16: =M16*Y$66 -> 1036.2934 | Z16: =N16*Z$66 -> 1212.359 | AA16: =O16*AA$66 -> 1214.9465 | AB16: =P16*AB$66 -> 1162.1435 | AC16: =Q16*AC$66 -> 1177.8838 | AD16: =R16*AD$66 -> 1006.8253 | AG16: 0.44791667 | AH16: =X16 -> 1356.8484 | AI16: =Y16 -> 1036.2934 | AJ16: =Z16 -> 1212.359 | AK16: =AA16 -> 1214.9465 | AL16: =AB16 -> 1162.1435 | AM16: =AC16 -> 1177.8838 | AN16: =AD16 -> 1006.8253
A17: 0.45833333 | B17: 1233.375 | C17: 975.125 | D17: 967 | E17: 1123.6 | F17: 1035.2 | G17: 1142.375 | H17: 1033.875 | K17: 0.45833333 | L17: =B17/$B$66 -> 0.97891019 | M17: =C17/$C$66 -> 0.7975814 | N17: =D17/$D$66 -> 0.76591584 | O17: =E17/$E$66 -> 0.86296212 | P17: =F17/$F$66 -> 0.82398419 | Q17: =G17/$G$66 -> 0.82756952 | R17: =H17/$H$66 -> 0.88692777 | W17: 0.45833333 | X17: =L17*X$66 -> 1181.9566 | Y17: =M17*Y$66 -> 934.47285 | Z17: =N17*Z$66 -> 926.68658 | AA17: =O17*AA$66 -> 1076.7581 | AB17: =P17*AB$66 -> 992.04337 | AC17: =Q17*AC$66 -> 1094.7503 | AD17: =R17*AD$66 -> 990.77361 | AG17: 0.45833333 | AH17: =X17 -> 1181.9566 | AI17: =Y17 -> 934.47285 | AJ17: =Z17 -> 926.68658 | AK17: =AA17 -> 1076.7581 | AL17: =AB17 -> 992.04337 | AM17: =AC17 -> 1094.7503 | AN17: =AD17 -> 990.77361
A18: 0.46875 | B18: 1003.375 | C18: 1097.25 | D18: 1454.7 | E18: 1203.1 | F18: 1286.2 | G18: 1169 | H18: 1198.375 | K18: 0.46875 | L18: =B18/$B$66 -> 0.79636284 | M18: =C18/$C$66 -> 0.89747078 | N18: =D18/$D$66 -> 1.1522004 | O18: =E18/$E$66 -> 0.92402076 | P18: =F18/$F$66 -> 1.0237717 | Q18: =G18/$G$66 -> 0.84685744 | R18: =H18/$H$66 -> 1.028047 | W18: 0.46875 | X18: =L18*X$66 -> 961.54513 | Y18: =M18*Y$66 -> 1051.5066 | Z18: =N18*Z$66 -> 1394.0548 | AA18: =O18*AA$66 -> 1152.9438 | AB18: =P18*AB$66 -> 1232.5794 | AC18: =Q18*AC$66 -> 1120.2654 | AD18: =R18*AD$66 -> 1148.4157 | AG18: 0.46875 | AH18: =X18 -> 961.54513 | AI18: =Y18 -> 1051.5066 | AJ18: =Z18 -> 1394.0548 | AK18: =AA18 -> 1152.9438 | AL18: =AB18 -> 1232.5794 | AM18: =AC18 -> 1120.2654 | AN18: =AD18 -> 1148.4157
A19: 0.47916667 | B19: 1115.5 | C19: 920 | D19: 1161.1 | E19: 1242.7 | F19: 1514.8 | G19: 1362.375 | H19: 1527.125 | K19: 0.47916667 | L19: =B19/$B$66 -> 0.88535467 | M19: =C19/$C$66 -> 0.75249316 | N19: =D19/$D$66 -> 0.91965345 | O19: =E19/$E$66 -> 0.95443488 | P19: =F19/$F$66 -> 1.2057296 | Q19: =G19/$G$66 -> 0.98694388 | R19: =H19/$H$66 -> 1.3100709 | W19: 0.47916667 | X19: =L19*X$66 -> 1068.9957 | Y19: =M19*Y$66 -> 881.64597 | Z19: =N19*Z$66 -> 1112.6947 | AA19: =O19*AA$66 -> 1190.8929 | AB19: =P19*AB$66 -> 1451.6493 | AC19: =Q19*AC$66 -> 1305.5787 | AD19: =R19*AD$66 -> 1463.4604 | AG19: 0.47916667 | AH19: =X19 -> 1068.9957 | AI19: =Y19 -> 881.64597 | AJ19: =Z19 -> 1112.6947 | AK19: =AA19 -> 1190.8929 | AL19: =AB19 -> 1451.6493 | AM19: =AC19 -> 1305.5787 | AN19: =AD19 -> 1463.4604
A20: 0.48958333 | B20: 1059.625 | C20: 1096.25 | D20: 1184.7 | E20: 1426.3 | F20: 1324 | G20: 1653.75 | H20: 1183.125 | K20: 0.48958333 | L20: =B20/$B$66 -> 0.84100757 | M20: =C20/$C$66 -> 0.89665285 | N20: =D20/$D$66 -> 0.93834591 | O20: =E20/$E$66 -> 1.0954458 | P20: =F20/$F$66 -> 1.0538592 | Q20: =G20/$G$66 -> 1.1980244 | R20: =H20/$H$66 -> 1.0149645 | W20: 0.48958333 | X20: =L20*X$66 -> 1015.4501 | Y20: =M20*Y$66 -> 1050.5483 | Z20: =N20*Z$66 -> 1135.3108 | AA20: =O20*AA$66 -> 1366.8387 | AB20: =P20*AB$66 -> 1268.8035 | AC20: =Q20*AC$66 -> 1584.8065 | AD20: =R20*AD$66 -> 1133.8015 | AG20: 0.48958333 | AH20: =X20 -> 1015.4501 | AI20: =Y20 -> 1050.5483 | AJ20: =Z20 -> 1135.3108 | AK20: =AA20 -> 1366.8387 | AL20: =AB20 -> 1268.8035 | AM20: =AC20 -> 1584.8065 | AN20: =AD20 -> 1133.8015
A21: 0.5 | B21: 952.75 | C21: 927.5 | D21: 1181 | E21: 1130.7 | F21: 1242.4 | G21: 1216.5 | H21: 912.625 | K21: 0.5 | L21: =B21/$B$66 -> 0.75618258 | M21: =C21/$C$66 -> 0.75862761 | N21: =D21/$D$66 -> 0.93541531 | O21: =E21/$E$66 -> 0.86841516 | P21: =F21/$F$66 -> 0.98890838 | Q21: =G21/$G$66 -> 0.88126781 | R21: =H21/$H$66 -> 0.78291133 | W21: 0.5 | X21: =L21*X$66 -> 913.03065 | Y21: =M21*Y$66 -> 888.8333 | Z21: =N21*Z$66 -> 1131.7651 | AA21: =O21*AA$66 -> 1083.5621 | AB21: =P21*AB$66 -> 1190.6054 | AC21: =Q21*AC$66 -> 1165.7851 | AD21: =R21*AD$66 -> 874.57842 | AG21: 0.5 | AH21: =X21 -> 913.03065 | AI21: =Y21 -> 888.8333 | AJ21: =Z21 -> 1131.7651 | AK21: =AA21 -> 1083.5621 | AL21: =AB21 -> 1190.6054 | AM21: =AC21 -> 1165.7851 | AN21: =AD21 -> 874.57842
A22: 0.51041667 | B22: 1133 | C22: 1400 | D22: 1862.7 | E22: 1941.5 | F22: 1208.2 | G22: 1686.75 | H22: 1326.75 | K22: 0.51041667 | L22: =B22/$B$66 -> 0.89924415 | M22: =C22/$C$66 -> 1.1450983 | N22: =D22/$D$66 -> 1.4753583 | O22: =E22/$E$66 -> 1.4911365 | P22: =F22/$F$66 -> 0.96168634 | Q22: =G22/$G$66 -> 1.2219305 | R22: =H22/$H$66 -> 1.1381757 | W22: 0.51041667 | X22: =L22*X$66 -> 1085.7662 | Y22: =M22*Y$66 -> 1341.6352 | Z22: =N22*Z$66 -> 1785.0456 | AA22: =O22*AA$66 -> 1860.5605 | AB22: =P22*AB$66 -> 1157.8311 | AC22: =Q22*AC$66 -> 1616.4308 | AD22: =R22*AD$66 -> 1271.4389 | AG22: 0.51041667 | AH22: =X22 -> 1085.7662 | AI22: =Y22 -> 1341.6352 | AJ22: =Z22 -> 1785.0456 | AK22: =AA22 -> 1860.5605 | AL22: =AB22 -> 1157.8311 | AM22: =AC22 -> 1616.4308 | AN22: =AD22 -> 1271.4389
A23: 0.52083333 | B23: 1570 | C23: 1309.375 | D23: 1768.7 | E23: 1994.3 | F23: 1252 | G23: 1508.125 | H23: 937.25 | K23: 0.52083333 | L23: =B23/$B$66 -> 1.2460841 | M23: =C23/$C$66 -> 1.0709736 | N23: =D23/$D$66 -> 1.4009052 | O23: =E23/$E$66 -> 1.5316886 | P23: =F23/$F$66 -> 0.99654966 | Q23: =G23/$G$66 -> 1.0925294 | R23: =H23/$H$66 -> 0.80403632 | W23: 0.52083333 | X23: =L23*X$66 -> 1504.548 | Y23: =M23*Y$66 -> 1254.7882 | Z23: =N23*Z$66 -> 1694.9644 | AA23: =O23*AA$66 -> 1911.1593 | AB23: =P23*AB$66 -> 1199.8052 | AC23: =Q23*AC$66 -> 1445.2525 | AD23: =R23*AD$66 -> 898.17683 | AG23: 0.52083333 | AH23: =X23 -> 1504.548 | AI23: =Y23 -> 1254.7882 | AJ23: =Z23 -> 1694.9644 | AK23: =AA23 -> 1911.1593 | AL23: =AB23 -> 1199.8052 | AM23: =AC23 -> 1445.2525 | AN23: =AD23 -> 898.17683
A24: 0.53125 | B24: 2206.625 | C24: 1004.875 | D24: 1231.1 | E24: 1437.5 | F24: 1380.1 | G24: 1318.25 | H24: 1470.875 | K24: 0.53125 | L24: =B24/$B$66 -> 1.7513633 | M24: =C24/$C$66 -> 0.82191474 | N24: =D24/$D$66 -> 0.9750972 | O24: =E24/$E$66 -> 1.1040478 | P24: =F24/$F$66 -> 1.0985129 | Q24: =G24/$G$66 -> 0.95497846 | R24: =H24/$H$66 -> 1.2618159 | W24: 0.53125 | X24: =L24*X$66 -> 2114.6326 | Y24: =M24*Y$66 -> 962.9826 | Z24: =N24*Z$66 -> 1179.7765 | AA24: =O24*AA$66 -> 1377.5718 | AB24: =P24*AB$66 -> 1322.5648 | AC24: =Q24*AC$66 -> 1263.2933 | AD24: =R24*AD$66 -> 1409.5554 | AG24: 0.53125 | AH24: =X24 -> 2114.6326 | AI24: =Y24 -> 962.9826 | AJ24: =Z24 -> 1179.7765 | AK24: =AA24 -> 1377.5718 | AL24: =AB24 -> 1322.5648 | AM24: =AC24 -> 1263.2933 | AN24: =AD24 -> 1409.5554
A25: 0.54166667 | B25: 1493 | C25: 1458.875 | D25: 1031.6 | E25: 1063.1 | F25: 1254.6 | G25: 1310.75 | H25: 1063 | K25: 0.54166667 | L25: =B25/$B$66 -> 1.1849704 | M25: =C25/$C$66 -> 1.1932538 | N25: =D25/$D$66 -> 0.8170825 | O25: =E25/$E$66 -> 0.81649611 | P25: =F25/$F$66 -> 0.99861917 | Q25: =G25/$G$66 -> 0.94954524 | R25: =H25/$H$66 -> 0.91191316 | W25: 0.54166667 | X25: =L25*X$66 -> 1430.7581 | Y25: =M25*Y$66 -> 1398.0557 | Z25: =N25*Z$66 -> 988.59346 | AA25: =O25*AA$66 -> 1018.7802 | AB25: =P25*AB$66 -> 1202.2968 | AC25: =Q25*AC$66 -> 1256.1059 | AD25: =R25*AD$66 -> 1018.6844 | AG25: 0.54166667 | AH25: =X25 -> 1430.7581 | AI25: =Y25 -> 1398.0557 | AJ25: =Z25 -> 988.59346 | AK25: =AA25 -> 1018.7802 | AL25: =AB25 -> 1202.2968 | AM25: =AC25 -> 1256.1059 | AN25: =AD25 -> 1018.6844
... A64: 0.94791667 | B64: 0 | C64: 0 | D64: 0 | E64: 0 | F64: 0 | G64: 0 | H64: 0 | K64: 0.94791667 | L64: =B64/$B$66 -> 0 | M64: =C64/$C$66 -> 0 | N64: =D64/$D$66 -> 0 | O64: =E64/$E$66 -> 0 | P64: =F64/$F$66 -> 0 | Q64: =G64/$G$66 -> 0 | R64: =H64/$H$66 -> 0 | W64: 0.94791667 | X64: =L64*X$66 -> 0 | Y64: =M64*Y$66 -> 0 | Z64: =N64*Z$66 -> 0 | AA64: =O64*AA$66 -> 0 | AB64: =P64*AB$66 -> 0 | AC64: =Q64*AC$66 -> 0 | AD64: =R64*AD$66 -> 0 | AG64: 0.94791667 | AH64: =X64 -> 0 | AI64: =Y64 -> 0 | AJ64: =Z64 -> 0 | AK64: =AA64 -> 0 | AL64: =AB64 -> 0 | AM64: =AC64 -> 0 | AN64: =AD64 -> 0
A65: 0.95833333 | C65: 0 | D65: 0 | F65: 0 | G65: 0 | H65: 0 | K65: 0.95833333 | L65: =B65/$B$66 -> 0 | M65: =C65/$C$66 -> 0 | N65: =D65/$D$66 -> 0 | O65: =E65/$E$66 -> 0 | P65: =F65/$F$66 -> 0 | Q65: =G65/$G$66 -> 0 | R65: =H65/$H$66 -> 0 | W65: 0.95833333 | X65: =L65*X$66 -> 0 | Y65: =M65*Y$66 -> 0 | Z65: =N65*Z$66 -> 0 | AA65: =O65*AA$66 -> 0 | AB65: =P65*AB$66 -> 0 | AC65: =Q65*AC$66 -> 0 | AD65: =R65*AD$66 -> 0 | AG65: 0.95833333 | AH65: =X65 -> 0 | AI65: =Y65 -> 0 | AJ65: =Z65 -> 0 | AK65: =AA65 -> 0 | AL65: =AB65 -> 0 | AM65: =AC65 -> 0 | AN65: =AD65 -> 0
A66: Total | B66: =SUMPRODUCT(B5:B65,'BREAKDOWN CALL VOLUME'!B5:B65)/SUM('BREAKDOWN CALL VOLUME'!B5:B65) -> 1259.947 | C66: =SUMPRODUCT(C5:C65,'BREAKDOWN CALL VOLUME'!C5:C65)/SUM('BREAKDOWN CALL VOLUME'!C5:C65) -> 1222.6025 | D66: =SUMPRODUCT(D5:D65,'BREAKDOWN CALL VOLUME'!D5:D65)/SUM('BREAKDOWN CALL VOLUME'!D5:D65) -> 1262.5408 | E66: =SUMPRODUCT(E5:E65,'BREAKDOWN CALL VOLUME'!E5:E65)/SUM('BREAKDOWN CALL VOLUME'!E5:E65) -> 1302.027 | F66: =SUMPRODUCT(F5:F65,'BREAKDOWN CALL VOLUME'!F5:F65)/SUM('BREAKDOWN CALL VOLUME'!F5:F65) -> 1256.3348 | G66: =SUMPRODUCT(G5:G65,'BREAKDOWN CALL VOLUME'!G5:G65)/SUM('BREAKDOWN CALL VOLUME'!G5:G65) -> 1380.3976 | H66: =SUMPRODUCT(H5:H65,'BREAKDOWN CALL VOLUME'!H5:H65)/SUM('BREAKDOWN CALL VOLUME'!H5:H65) -> 1165.6812 | I66: =SUMPRODUCT(B66:H66,'BREAKDOWN CALL VOLUME'!B66:H66)/SUM('BREAKDOWN CALL VOLUME'!B66:H66) -> 1266.8124 | L66: =B67 -> 0.99458064 | M66: =C67 -> 0.96510148 | N66: =D67 -> 0.99662811 | O66: =E67 -> 1.0277979 | P66: =F67 -> 0.99172919 | Q66: =G67 -> 1.0896623 | R66: =H67 -> 0.92016878 | W66: Total | X66: =L66*$W$3 -> 1207.4209 | Y66: =M66*$W$3 -> 1171.6332 | Z66: =N66*$W$3 -> 1209.9065 | AA66: =O66*$W$3 -> 1247.7466 | AB66: =P66*$W$3 -> 1203.9592 | AC66: =Q66*$W$3 -> 1322.85 | AD66: =R66*$W$3 -> 1117.0849 | AG66: Total | AH66: 1145.4118 | AI66: 1189.0079 | AJ66: 1234.9941 | AK66: 1264.5529 | AL66: 1245.7164 | AM66: 1252.3939 | AN66: 1148.415
A67: Dow profile | B67: =B66/$I$66 -> 0.99458064 | C67: =C66/$I$66 -> 0.96510148 | D67: =D66/$I$66 -> 0.99662811 | E67: =E66/$I$66 -> 1.0277979 | F67: =F66/$I$66 -> 0.99172919 | G67: =G66/$I$66 -> 1.0896623 | H67: =H66/$I$66 -> 0.92016878

Sheet BREAKDOWN SHRINKAGE
A1: DEFAULT SHRINKAGE (WE MUST USE THE BETTER BASED ON OUR CAMPAING, NEED AN ANALYSIS)
A3: Dow profile | B3: =B67 -> 1 | C3: =C67 -> 1 | D3: =D67 -> 1 | E3: =E67 -> 1 | F3: =F67 -> 1 | G3: =G67 -> 1 | H3: =H67 -> 1 | K3: Distribution% | V3: Shrinkage | W3: 0.15
A4: INTERVAL | B4: MONDAY | C4: TUESDAY | D4: WEDNESDAY | E4: THURSDAY | F4: FRIDAY | G4: SATURDAY | H4: SUNDAY | K4: INTERVAL | L4: MONDAY | M4: TUESDAY | N4: WEDNESDAY | O4: THURSDAY | P4: FRIDAY | Q4: SATURDAY | R4: SUNDAY | W4: INTERVAL | X4: MONDAY | Y4: TUESDAY | Z4: WEDNESDAY | AA4: THURSDAY | AB4: FRIDAY | AC4: SATURDAY | AD4: SUNDAY
A5: 0.33333333 | B5: 0.15 | C5: 0.15 | D5: 0.15 | E5: 0.15 | F5: 0.15 | G5: 0.15 | H5: 0.15 | K5: 0.33333333 | L5: =B5/B66 -> 1 | M5: =C5/$C$66 -> 1 | N5: =D5/$D$66 -> 1 | O5: =E5/$E$66 -> 1 | P5: =F5/$F$66 -> 1 | Q5: =G5/$G$66 -> 1 | R5: =H5/$H$66 -> 1 | T5: Row Labels | U5: Average of Shrinkage% | W5: 0.33333333 | X5: =L5*X$66 -> 0.15 | Y5: =M5*Y$66 -> 0.15 | Z5: =N5*Z$66 -> 0.15 | AA5: =O5*AA$66 -> 0.15 | AB5: =P5*AB$66 -> 0.15 | AC5: =Q5*AC$66 -> 0.15 | AD5: =R5*AD$66 -> 0.15
A6: 0.34375 | B6: 0.15 | C6: 0.15 | D6: 0.15 | E6: 0.15 | F6: 0.15 | G6: 0.15 | H6: 0.15 | K6: 0.34375 | L6: =B6/$B$66 -> 1 | M6: =C6/$C$66 -> 1 | N6: =D6/$D$66 -> 1 | O6: =E6/$E$66 -> 1 | P6: =F6/$F$66 -> 1 | Q6: =G6/$G$66 -> 1 | R6: =H6/$H$66 -> 1 | T6: 45992 | U6: 0.15 | W6: 0.34375 | X6: =L6*X$66 -> 0.15 | Y6: =M6*Y$66 -> 0.15 | Z6: =N6*Z$66 -> 0.15 | AA6: =O6*AA$66 -> 0.15 | AB6: =P6*AB$66 -> 0.15 | AC6: =Q6*AC$66 -> 0.15 | AD6: =R6*AD$66 -> 0.15
A7: 0.35416667 | B7: 0.15 | C7: 0.15 | D7: 0.15 | E7: 0.15 | F7: 0.15 | G7: 0.15 | H7: 0.15 | K7: 0.35416667 | L7: =B7/$B$66 -> 1 | M7: =C7/$C$66 -> 1 | N7: =D7/$D$66 -> 1 | O7: =E7/$E$66 -> 1 | P7: =F7/$F$66 -> 1 | Q7: =G7/$G$66 -> 1 | R7: =H7/$H$66 -> 1 | T7: 45993 | U7: 0.15 | W7: 0.35416667 | X7: =L7*X$66 -> 0.15 | Y7: =M7*Y$66 -> 0.15 | Z7: =N7*Z$66 -> 0.15 | AA7: =O7*AA$66 -> 0.15 | AB7: =P7*AB$66 -> 0.15 | AC7: =Q7*AC$66 -> 0.15 | AD7: =R7*AD$66 -> 0.15
A8: 0.36458333 | B8: 0.15 | C8: 0.15 | D8: 0.15 | E8: 0.15 | F8: 0.15 | G8: 0.15 | H8: 0.15 | K8: 0.36458333 | L8: =B8/$B$66 -> 1 | M8: =C8/$C$66 -> 1 | N8: =D8/$D$66 -> 1 | O8: =E8/$E$66 -> 1 | P8: =F8/$F$66 -> 1 | Q8: =G8/$G$66 -> 1 | R8: =H8/$H$66 -> 1 | T8: 45994 | U8: 0.15 | W8: 0.36458333 | X8: =L8*X$66 -> 0.15 | Y8: =M8*Y$66 -> 0.15 | Z8: =N8*Z$66 -> 0.15 | AA8: =O8*AA$66 -> 0.15 | AB8: =P8*AB$66 -> 0.15 | AC8: =Q8*AC$66 -> 0.15 | AD8: =R8*AD$66 -> 0.15
A9: 0.375 | B9: 0.15 | C9: 0.15 | D9: 0.15 | E9: 0.15 | F9: 0.15 | G9: 0.15 | H9: 0.15 | K9: 0.375 | L9: =B9/$B$66 -> 1 | M9: =C9/$C$66 -> 1 | N9: =D9/$D$66 -> 1 | O9: =E9/$E$66 -> 1 | P9: =F9/$F$66 -> 1 | Q9: =G9/$G$66 -> 1 | R9: =H9/$H$66 -> 1 | T9: 45995 | U9: 0.15 | W9: 0.375 | X9: =L9*X$66 -> 0.15 | Y9: =M9*Y$66 -> 0.15 | Z9: =N9*Z$66 -> 0.15 | AA9: =O9*AA$66 -> 0.15 | AB9: =P9*AB$66 -> 0.15 | AC9: =Q9*AC$66 -> 0.15 | AD9: =R9*AD$66 -> 0.15
A10: 0.38541667 | B10: 0.15 | C10: 0.15 | D10: 0.15 | E10: 0.15 | F10: 0.15 | G10: 0.15 | H10: 0.15 | K10: 0.38541667 | L10: =B10/$B$66 -> 1 | M10: =C10/$C$66 -> 1 | N10: =D10/$D$66 -> 1 | O10: =E10/$E$66 -> 1 | P10: =F10/$F$66 -> 1 | Q10: =G10/$G$66 -> 1 | R10: =H10/$H$66 -> 1 | T10: 45996 | U10: 0.15 | W10: 0.38541667 | X10: =L10*X$66 -> 0.15 | Y10: =M10*Y$66 -> 0.15 | Z10: =N10*Z$66 -> 0.15 | AA10: =O10*AA$66 -> 0.15 | AB10: =P10*AB$66 -> 0.15 | AC10: =Q10*AC$66 -> 0.15 | AD10: =R10*AD$66 -> 0.15
A11: 0.39583333 | B11: 0.15 | C11: 0.15 | D11: 0.15 | E11: 0.15 | F11: 0.15 | G11: 0.15 | H11: 0.15 | K11: 0.39583333 | L11: =B11/$B$66 -> 1 | M11: =C11/$C$66 -> 1 | N11: =D11/$D$66 -> 1 | O11: =E11/$E$66 -> 1 | P11: =F11/$F$66 -> 1 | Q11: =G11/$G$66 -> 1 | R11: =H11/$H$66 -> 1 | T11: 45997 | U11: 0.15 | W11: 0.39583333 | X11: =L11*X$66 -> 0.15 | Y11: =M11*Y$66 -> 0.15 | Z11: =N11*Z$66 -> 0.15 | AA11: =O11*AA$66 -> 0.15 | AB11: =P11*AB$66 -> 0.15 | AC11: =Q11*AC$66 -> 0.15 | AD11: =R11*AD$66 -> 0.15
A12: 0.40625 | B12: 0.15 | C12: 0.15 | D12: 0.15 | E12: 0.15 | F12: 0.15 | G12: 0.15 | H12: 0.15 | K12: 0.40625 | L12: =B12/$B$66 -> 1 | M12: =C12/$C$66 -> 1 | N12: =D12/$D$66 -> 1 | O12: =E12/$E$66 -> 1 | P12: =F12/$F$66 -> 1 | Q12: =G12/$G$66 -> 1 | R12: =H12/$H$66 -> 1 | T12: 45998 | U12: 0.15 | W12: 0.40625 | X12: =L12*X$66 -> 0.15 | Y12: =M12*Y$66 -> 0.15 | Z12: =N12*Z$66 -> 0.15 | AA12: =O12*AA$66 -> 0.15 | AB12: =P12*AB$66 -> 0.15 | AC12: =Q12*AC$66 -> 0.15 | AD12: =R12*AD$66 -> 0.15
A13: 0.41666667 | B13: 0.15 | C13: 0.15 | D13: 0.15 | E13: 0.15 | F13: 0.15 | G13: 0.15 | H13: 0.15 | K13: 0.41666667 | L13: =B13/$B$66 -> 1 | M13: =C13/$C$66 -> 1 | N13: =D13/$D$66 -> 1 | O13: =E13/$E$66 -> 1 | P13: =F13/$F$66 -> 1 | Q13: =G13/$G$66 -> 1 | R13: =H13/$H$66 -> 1 | T13: Grand Total | U13: 0.15 | W13: 0.41666667 | X13: =L13*X$66 -> 0.15 | Y13: =M13*Y$66 -> 0.15 | Z13: =N13*Z$66 -> 0.15 | AA13: =O13*AA$66 -> 0.15 | AB13: =P13*AB$66 -> 0.15 | AC13: =Q13*AC$66 -> 0.15 | AD13: =R13*AD$66 -> 0.15
A14: 0.42708333 | B14: 0.15 | C14: 0.15 | D14: 0.15 | E14: 0.15 | F14: 0.15 | G14: 0.15 | H14: 0.15 | K14: 0.42708333 | L14: =B14/$B$66 -> 1 | M14: =C14/$C$66 -> 1 | N14: =D14/$D$66 -> 1 | O14: =E14/$E$66 -> 1 | P14: =F14/$F$66 -> 1 | Q14: =G14/$G$66 -> 1 | R14: =H14/$H$66 -> 1 | W14: 0.42708333 | X14: =L14*X$66 -> 0.15 | Y14: =M14*Y$66 -> 0.15 | Z14: =N14*Z$66 -> 0.15 | AA14: =O14*AA$66 -> 0.15 | AB14: =P14*AB$66 -> 0.15 | AC14: =Q14*AC$66 -> 0.15 | AD14: =R14*AD$66 -> 0.15
A15: 0.4375 | B15: 0.15 | C15: 0.15 | D15: 0.15 | E15: 0.15 | F15: 0.15 | G15: 0.15 | H15: 0.15 | K15: 0.4375 | L15: =B15/$B$66 -> 1 | M15: =C15/$C$66 -> 1 | N15: =D15/$D$66 -> 1 | O15: =E15/$E$66 -> 1 | P15: =F15/$F$66 -> 1 | Q15: =G15/$G$66 -> 1 | R15: =H15/$H$66 -> 1 | W15: 0.4375 | X15: =L15*X$66 -> 0.15 | Y15: =M15*Y$66 -> 0.15 | Z15: =N15*Z$66 -> 0.15 | AA15: =O15*AA$66 -> 0.15 | AB15: =P15*AB$66 -> 0.15 | AC15: =Q15*AC$66 -> 0.15 | AD15: =R15*AD$66 -> 0.15
A16: 0.44791667 | B16: 0.15 | C16: 0.15 | D16: 0.15 | E16: 0.15 | F16: 0.15 | G16: 0.15 | H16: 0.15 | K16: 0.44791667 | L16: =B16/$B$66 -> 1 | M16: =C16/$C$66 -> 1 | N16: =D16/$D$66 -> 1 | O16: =E16/$E$66 -> 1 | P16: =F16/$F$66 -> 1 | Q16: =G16/$G$66 -> 1 | R16: =H16/$H$66 -> 1 | W16: 0.44791667 | X16: =L16*X$66 -> 0.15 | Y16: =M16*Y$66 -> 0.15 | Z16: =N16*Z$66 -> 0.15 | AA16: =O16*AA$66 -> 0.15 | AB16: =P16*AB$66 -> 0.15 | AC16: =Q16*AC$66 -> 0.15 | AD16: =R16*AD$66 -> 0.15
A17: 0.45833333 | B17: 0.15 | C17: 0.15 | D17: 0.15 | E17: 0.15 | F17: 0.15 | G17: 0.15 | H17: 0.15 | K17: 0.45833333 | L17: =B17/$B$66 -> 1 | M17: =C17/$C$66 -> 1 | N17: =D17/$D$66 -> 1 | O17: =E17/$E$66 -> 1 | P17: =F17/$F$66 -> 1 | Q17: =G17/$G$66 -> 1 | R17: =H17/$H$66 -> 1 | W17: 0.45833333 | X17: =L17*X$66 -> 0.15 | Y17: =M17*Y$66 -> 0.15 | Z17: =N17*Z$66 -> 0.15 | AA17: =O17*AA$66 -> 0.15 | AB17: =P17*AB$66 -> 0.15 | AC17: =Q17*AC$66 -> 0.15 | AD17: =R17*AD$66 -> 0.15
A18: 0.46875 | B18: 0.15 | C18: 0.15 | D18: 0.15 | E18: 0.15 | F18: 0.15 | G18: 0.15 | H18: 0.15 | K18: 0.46875 | L18: =B18/$B$66 -> 1 | M18: =C18/$C$66 -> 1 | N18: =D18/$D$66 -> 1 | O18: =E18/$E$66 -> 1 | P18: =F18/$F$66 -> 1 | Q18: =G18/$G$66 -> 1 | R18: =H18/$H$66 -> 1 | W18: 0.46875 | X18: =L18*X$66 -> 0.15 | Y18: =M18*Y$66 -> 0.15 | Z18: =N18*Z$66 -> 0.15 | AA18: =O18*AA$66 -> 0.15 | AB18: =P18*AB$66 -> 0.15 | AC18: =Q18*AC$66 -> 0.15 | AD18: =R18*AD$66 -> 0.15
A19: 0.47916667 | B19: 0.15 | C19: 0.15 | D19: 0.15 | E19: 0.15 | F19: 0.15 | G19: 0.15 | H19: 0.15 | K19: 0.47916667 | L19: =B19/$B$66 -> 1 | M19: =C19/$C$66 -> 1 | N19: =D19/$D$66 -> 1 | O19: =E19/$E$66 -> 1 | P19: =F19/$F$66 -> 1 | Q19: =G19/$G$66 -> 1 | R19: =H19/$H$66 -> 1 | W19: 0.47916667 | X19: =L19*X$66 -> 0.15 | Y19: =M19*Y$66 -> 0.15 | Z19: =N19*Z$66 -> 0.15 | AA19: =O19*AA$66 -> 0.15 | AB19: =P19*AB$66 -> 0.15 | AC19: =Q19*AC$66 -> 0.15 | AD19: =R19*AD$66 -> 0.15
A20: 0.48958333 | B20: 0.15 | C20: 0.15 | D20: 0.15 | E20: 0.15 | F20: 0.15 | G20: 0.15 | H20: 0.15 | K20: 0.48958333 | L20: =B20/$B$66 -> 1 | M20: =C20/$C$66 -> 1 | N20: =D20/$D$66 -> 1 | O20: =E20/$E$66 -> 1 | P20: =F20/$F$66 -> 1 | Q20: =G20/$G$66 -> 1 | R20: =H20/$H$66 -> 1 | W20: 0.48958333 | X20: =L20*X$66 -> 0.15 | Y20: =M20*Y$66 -> 0.15 | Z20: =N20*Z$66 -> 0.15 | AA20: =O20*AA$66 -> 0.15 | AB20: =P20*AB$66 -> 0.15 | AC20: =Q20*AC$66 -> 0.15 | AD20: =R20*AD$66 -> 0.15
A21: 0.5 | B21: 0.15 | C21: 0.15 | D21: 0.15 | E21: 0.15 | F21: 0.15 | G21: 0.15 | H21: 0.15 | K21: 0.5 | L21: =B21/$B$66 -> 1 | M21: =C21/$C$66 -> 1 | N21: =D21/$D$66 -> 1 | O21: =E21/$E$66 -> 1 | P21: =F21/$F$66 -> 1 | Q21: =G21/$G$66 -> 1 | R21: =H21/$H$66 -> 1 | W21: 0.5 | X21: =L21*X$66 -> 0.15 | Y21: =M21*Y$66 -> 0.15 | Z21: =N21*Z$66 -> 0.15 | AA21: =O21*AA$66 -> 0.15 | AB21: =P21*AB$66 -> 0.15 | AC21: =Q21*AC$66 -> 0.15 | AD21: =R21*AD$66 -> 0.15
A22: 0.51041667 | B22: 0.15 | C22: 0.15 | D22: 0.15 | E22: 0.15 | F22: 0.15 | G22: 0.15 | H22: 0.15 | K22: 0.51041667 | L22: =B22/$B$66 -> 1 | M22: =C22/$C$66 -> 1 | N22: =D22/$D$66 -> 1 | O22: =E22/$E$66 -> 1 | P22: =F22/$F$66 -> 1 | Q22: =G22/$G$66 -> 1 | R22: =H22/$H$66 -> 1 | W22: 0.51041667 | X22: =L22*X$66 -> 0.15 | Y22: =M22*Y$66 -> 0.15 | Z22: =N22*Z$66 -> 0.15 | AA22: =O22*AA$66 -> 0.15 | AB22: =P22*AB$66 -> 0.15 | AC22: =Q22*AC$66 -> 0.15 | AD22: =R22*AD$66 -> 0.15
A23: 0.52083333 | B23: 0.15 | C23: 0.15 | D23: 0.15 | E23: 0.15 | F23: 0.15 | G23: 0.15 | H23: 0.15 | K23: 0.52083333 | L23: =B23/$B$66 -> 1 | M23: =C23/$C$66 -> 1 | N23: =D23/$D$66 -> 1 | O23: =E23/$E$66 -> 1 | P23: =F23/$F$66 -> 1 | Q23: =G23/$G$66 -> 1 | R23: =H23/$H$66 -> 1 | W23: 0.52083333 | X23: =L23*X$66 -> 0.15 | Y23: =M23*Y$66 -> 0.15 | Z23: =N23*Z$66 -> 0.15 | AA23: =O23*AA$66 -> 0.15 | AB23: =P23*AB$66 -> 0.15 | AC23: =Q23*AC$66 -> 0.15 | AD23: =R23*AD$66 -> 0.15
A24: 0.53125 | B24: 0.15 | C24: 0.15 | D24: 0.15 | E24: 0.15 | F24: 0.15 | G24: 0.15 | H24: 0.15 | K24: 0.53125 | L24: =B24/$B$66 -> 1 | M24: =C24/$C$66 -> 1 | N24: =D24/$D$66 -> 1 | O24: =E24/$E$66 -> 1 | P24: =F24/$F$66 -> 1 | Q24: =G24/$G$66 -> 1 | R24: =H24/$H$66 -> 1 | W24: 0.53125 | X24: =L24*X$66 -> 0.15 | Y24: =M24*Y$66 -> 0.15 | Z24: =N24*Z$66 -> 0.15 | AA24: =O24*AA$66 -> 0.15 | AB24: =P24*AB$66 -> 0.15 | AC24: =Q24*AC$66 -> 0.15 | AD24: =R24*AD$66 -> 0.15
A25: 0.54166667 | B25: 0.15 | C25: 0.15 | D25: 0.15 | E25: 0.15 | F25: 0.15 | G25: 0.15 | H25: 0.15 | K25: 0.54166667 | L25: =B25/$B$66 -> 1 | M25: =C25/$C$66 -> 1 | N25: =D25/$D$66 -> 1 | O25: =E25/$E$66 -> 1 | P25: =F25/$F$66 -> 1 | Q25: =G25/$G$66 -> 1 | R25: =H25/$H$66 -> 1 | W25: 0.54166667 | X25: =L25*X$66 -> 0.15 | Y25: =M25*Y$66 -> 0.15 | Z25: =N25*Z$66 -> 0.15 | AA25: =O25*AA$66 -> 0.15 | AB25: =P25*AB$66 -> 0.15 | AC25: =Q25*AC$66 -> 0.15 | AD25: =R25*AD$66 -> 0.15
... A65: 0.95833333 | B65: 0.15 | C65: 0.15 | D65: 0.15 | E65: 0.15 | F65: 0.15 | G65: 0.15 | H65: 0.15 | K65: 0.95833333 | L65: =B65/$B$66 -> 1 | M65: =C65/$C$66 -> 1 | N65: =D65/$D$66 -> 1 | O65: =E65/$E$66 -> 1 | P65: =F65/$F$66 -> 1 | Q65: =G65/$G$66 -> 1 | R65: =H65/$H$66 -> 1 | W65: 0.95833333 | X65: =L65*X$66 -> 0.15 | Y65: =M65*Y$66 -> 0.15 | Z65: =N65*Z$66 -> 0.15 | AA65: =O65*AA$66 -> 0.15 | AB65: =P65*AB$66 -> 0.15 | AC65: =Q65*AC$66 -> 0.15 | AD65: =R65*AD$66 -> 0.15
A66: Total | B66: =SUMPRODUCT(B5:B65,'BREAKDOWN CALL VOLUME'!B5:B65)/SUM('BREAKDOWN CALL VOLUME'!B5:B65) -> 0.15 | C66: =SUMPRODUCT(C5:C65,'BREAKDOWN CALL VOLUME'!C5:C65)/SUM('BREAKDOWN CALL VOLUME'!C5:C65) -> 0.15 | D66: =SUMPRODUCT(D5:D65,'BREAKDOWN CALL VOLUME'!D5:D65)/SUM('BREAKDOWN CALL VOLUME'!D5:D65) -> 0.15 | E66: =SUMPRODUCT(E5:E65,'BREAKDOWN CALL VOLUME'!E5:E65)/SUM('BREAKDOWN CALL VOLUME'!E5:E65) -> 0.15 | F66: =SUMPRODUCT(F5:F65,'BREAKDOWN CALL VOLUME'!F5:F65)/SUM('BREAKDOWN CALL VOLUME'!F5:F65) -> 0.15 | G66: =SUMPRODUCT(G5:G65,'BREAKDOWN CALL VOLUME'!G5:G65)/SUM('BREAKDOWN CALL VOLUME'!G5:G65) -> 0.15 | H66: =SUMPRODUCT(H5:H65,'BREAKDOWN CALL VOLUME'!H5:H65)/SUM('BREAKDOWN CALL VOLUME'!H5:H65) -> 0.15 | I66: =SUMPRODUCT(B66:H66,'BREAKDOWN CALL VOLUME'!B66:H66)/SUM('BREAKDOWN CALL VOLUME'!B66:H66) -> 0.15 | L66: =B67 -> 1 | M66: =C67 -> 1 | N66: =D67 -> 1 | O66: =E67 -> 1 | P66: =F67 -> 1 | Q66: =G67 -> 1 | R66: =H67 -> 1 | W66: Total | X66: =L66*$W$3 -> 0.15 | Y66: =M66*$W$3 -> 0.15 | Z66: =N66*$W$3 -> 0.15 | AA66: =O66*$W$3 -> 0.15 | AB66: =P66*$W$3 -> 0.15 | AC66: =Q66*$W$3 -> 0.15 | AD66: =R66*$W$3 -> 0.15
A67: Dow profile | B67: =B66/$I$66 -> 1 | C67: =C66/$I$66 -> 1 | D67: =D66/$I$66 -> 1 | E67: =E66/$I$66 -> 1 | F67: =F66/$I$66 -> 1 | G67: =G66/$I$66 -> 1 | H67: =H66/$I$66 -> 1

Sheet REQUIREMENTS
B2: Volume | C2: 10901 | K2: AHT | L2: 1214 | T2: Shrinkage | U2: 0.15 | AC2: Occupancy% | AD2: 0.75 | AL2: Requirements
B3: INTERVAL | C3: MONDAY | D3: TUESDAY | E3: WEDNESDAY | F3: THURSDAY | G3: FRIDAY | H3: SATURDAY | I3: SUNDAY | K3: INTERVAL | L3: MONDAY | M3: TUESDAY | N3: WEDNESDAY | O3: THURSDAY | P3: FRIDAY | Q3: SATURDAY | R3: SUNDAY | T3: INTERVAL | U3: MONDAY | V3: TUESDAY | W3: WEDNESDAY | X3: THURSDAY | Y3: FRIDAY | Z3: SATURDAY | AA3: SUNDAY | AC3: INTERVAL | AD3: MONDAY | AE3: TUESDAY | AF3: WEDNESDAY | AG3: THURSDAY | AH3: FRIDAY | AI3: SATURDAY | AJ3: SUNDAY | AL3: INTERVAL | AM3: MONDAY | AN3: TUESDAY | AO3: WEDNESDAY | AP3: THURSDAY | AQ3: FRIDAY | AR3: SATURDAY | AS3: SUNDAY
B4: 0.33333333 | C4: ='BREAKDOWN CALL VOLUME'!W5 -> 23.95364 | D4: ='BREAKDOWN CALL VOLUME'!X5 -> 23.189743 | E4: ='BREAKDOWN CALL VOLUME'!Y5 -> 23.02605 | F4: ='BREAKDOWN CALL VOLUME'!Z5 -> 21.205594 | G4: ='BREAKDOWN CALL VOLUME'!AA5 -> 22.879719 | H4: ='BREAKDOWN CALL VOLUME'!AB5 -> 13.953771 | I4: ='BREAKDOWN CALL VOLUME'!AC5 -> 6.1384613 | K4: 0.33333333 | L4: ='BREAKDOWN AHT'!X5 -> 370.02777 | M4: ='BREAKDOWN AHT'!Y5 -> 375.53806 | N4: ='BREAKDOWN AHT'!Z5 -> 376.80782 | O4: ='BREAKDOWN AHT'!AA5 -> 404.69467 | P4: ='BREAKDOWN AHT'!AB5 -> 364.44561 | Q4: ='BREAKDOWN AHT'!AC5 -> 337.92436 | R4: ='BREAKDOWN AHT'!AD5 -> 306.65947 | T4: 0.33333333 | U4: ='BREAKDOWN SHRINKAGE'!X5 -> 0.15 | V4: ='BREAKDOWN SHRINKAGE'!Y5 -> 0.15 | W4: ='BREAKDOWN SHRINKAGE'!Z5 -> 0.15 | X4: ='BREAKDOWN SHRINKAGE'!AA5 -> 0.15 | Y4: ='BREAKDOWN SHRINKAGE'!AB5 -> 0.15 | Z4: ='BREAKDOWN SHRINKAGE'!AC5 -> 0.15 | AA4: ='BREAKDOWN SHRINKAGE'!AD5 -> 0.15 | AC4: 0.33333333 | AD4: 0.75 | AE4: 0.75 | AF4: 0.75 | AG4: 0.75 | AH4: 0.75 | AI4: 0.75 | AJ4: 0.75 | AL4: 0.33333333 | AM4: =(C4*L4)/(1800*AD4) -> 6.5655645 | AN4: =(D4*M4)/(1800*AE4) -> 6.4508378 | AO4: =(E4*N4)/(1800*AF4) -> 6.4269599 | AP4: =(F4*O4)/(1800*AG4) -> 6.3568819 | AQ4: =(G4*P4)/(1800*AH4) -> 6.1766025 | AR4: =(H4*Q4)/(1800*AI4) -> 3.4928289 | AS4: =(I4*R4)/(1800*AJ4) -> 1.3943832
B5: 0.34375 | C5: ='BREAKDOWN CALL VOLUME'!W6 -> 21.007179 | D5: ='BREAKDOWN CALL VOLUME'!X6 -> 18.715487 | E5: ='BREAKDOWN CALL VOLUME'!Y6 -> 20.424335 | F5: ='BREAKDOWN CALL VOLUME'!Z6 -> 18.582797 | G5: ='BREAKDOWN CALL VOLUME'!AA6 -> 19.252447 | H5: ='BREAKDOWN CALL VOLUME'!AB6 -> 12.037373 | I5: ='BREAKDOWN CALL VOLUME'!AC6 -> 6.0215383 | K5: 0.34375 | L5: ='BREAKDOWN AHT'!X6 -> 726.63919 | M5: ='BREAKDOWN AHT'!Y6 -> 812.76738 | N5: ='BREAKDOWN AHT'!Z6 -> 928.79486 | O5: ='BREAKDOWN AHT'!AA6 -> 1275.895 | P5: ='BREAKDOWN AHT'!AB6 -> 916.43265 | Q5: ='BREAKDOWN AHT'!AC6 -> 573.9084 | R5: ='BREAKDOWN AHT'!AD6 -> 690.22338 | T5: 0.34375 | U5: ='BREAKDOWN SHRINKAGE'!X6 -> 0.15 | V5: ='BREAKDOWN SHRINKAGE'!Y6 -> 0.15 | W5: ='BREAKDOWN SHRINKAGE'!Z6 -> 0.15 | X5: ='BREAKDOWN SHRINKAGE'!AA6 -> 0.15 | Y5: ='BREAKDOWN SHRINKAGE'!AB6 -> 0.15 | Z5: ='BREAKDOWN SHRINKAGE'!AC6 -> 0.15 | AA5: ='BREAKDOWN SHRINKAGE'!AD6 -> 0.15 | AC5: 0.34375 | AD5: 0.75 | AE5: 0.75 | AF5: 0.75 | AG5: 0.75 | AH5: 0.75 | AI5: 0.75 | AJ5: 0.75 | AL5: 0.34375 | AM5: =(C5*L5)/(1800*AD5) -> 11.30714 | AN5: =(D5*M5)/(1800*AE5) -> 11.267657 | AO5: =(E5*N5)/(1800*AF5) -> 14.051865 | AP5: =(F5*O5)/(1800*AG5) -> 17.562739 | AQ5: =(G5*P5)/(1800*AH5) -> 13.069312 | AR5: =(H5*Q5)/(1800*AI5) -> 5.1172959 | AS5: =(I5*R5)/(1800*AJ5) -> 3.0786715
B6: 0.35416667 | C6: ='BREAKDOWN CALL VOLUME'!W7 -> 18.442666 | D6: ='BREAKDOWN CALL VOLUME'!X7 -> 20.188717 | E6: ='BREAKDOWN CALL VOLUME'!Y7 -> 19.754685 | F6: ='BREAKDOWN CALL VOLUME'!Z7 -> 18.303776 | G6: ='BREAKDOWN CALL VOLUME'!AA7 -> 18.471188 | H6: ='BREAKDOWN CALL VOLUME'!AB7 -> 13.175234 | I6: ='BREAKDOWN CALL VOLUME'!AC7 -> 7.1323074 | K6: 0.35416667 | L6: ='BREAKDOWN AHT'!X7 -> 1195.4928 | M6: ='BREAKDOWN AHT'!Y7 -> 1261.3766 | N6: ='BREAKDOWN AHT'!Z7 -> 1249.829 | O6: ='BREAKDOWN AHT'!AA7 -> 1247.2415 | P6: ='BREAKDOWN AHT'!AB7 -> 962.5274 | Q6: ='BREAKDOWN AHT'!AC7 -> 1289.6468 | R6: ='BREAKDOWN AHT'!AD7 -> 1005.867 | T6: 0.35416667 | U6: ='BREAKDOWN SHRINKAGE'!X7 -> 0.15 | V6: ='BREAKDOWN SHRINKAGE'!Y7 -> 0.15 | W6: ='BREAKDOWN SHRINKAGE'!Z7 -> 0.15 | X6: ='BREAKDOWN SHRINKAGE'!AA7 -> 0.15 | Y6: ='BREAKDOWN SHRINKAGE'!AB7 -> 0.15 | Z6: ='BREAKDOWN SHRINKAGE'!AC7 -> 0.15 | AA6: ='BREAKDOWN SHRINKAGE'!AD7 -> 0.15 | AC6: 0.35416667 | AD6: 0.75 | AE6: 0.75 | AF6: 0.75 | AG6: 0.75 | AH6: 0.75 | AI6: 0.75 | AJ6: 0.75 | AL6: 0.35416667 | AM6: =(C6*L6)/(1800*AD6) -> 16.331907 | AN6: =(D6*M6)/(1800*AE6) -> 18.86339 | AO6: =(E6*N6)/(1800*AF6) -> 18.288872 | AP6: =(F6*O6)/(1800*AG6) -> 16.91054 | AQ6: =(G6*P6)/(1800*AH6) -> 13.169648 | AR6: =(H6*Q6)/(1800*AI6) -> 12.586221 | AS6: =(I6*R6)/(1800*AJ6) -> 5.3141872
